Workbook
Name G872_: '攤位整理表 請在此填寫資訊'!$G$866

Sheet FF47 攤位整理表單操作手冊
B2: FF47 攤位整理表單 使用說明 | I2: 攤位名稱 | J2: 徵求寄攤 | K2: 第一天攤位編號 | L2: 第二天攤位編號 | M2: 第三天攤位編號 | N2: 筆名 | O2: 創作者類型 | P2: 商品年齡分類 (一般、R15 (明顯性暗示)、R18) | Q2: 作品類型 (原創、二創) | R2: 二創參考作品 (原創免填) | S2: 販售資訊 | T2: 商品備註 (特殊標籤) | U2: 場前印調 | V2: FB (1) | W2: FB (2) | X2: Bluesky(1) | Y2: Bluesky(2) | Z2: TWITTER (1) | AA2: TWITTER (2) | AB2: PLURK | AC2: Pixiv | AD2: Fanbox | AE2: Fantia | AF2: 可洛斯 | AG2: 其他贊助平台 | AH2: IG | AI2: YOUTUBE | AJ2: TWITCH | AK2: LINE | AL2: DISCORD | AM2: 巴哈姆特 | AN2: 官方網站 | AO2: Linktree等連結整合網頁 | AP2: 其他連結 | AQ2: 預告 | AR2: 品書 | AS2: 預購/通販 | AT2: 賣場 | AU2: 縮圖 | AV2: 有無縮圖 | AW2: 試閱
B4: 前言 | C4: 大家好! 這裡是加帕利天藍怪預警中心小編，也是場次攤位整理人員，在此歡迎各位攤主們使用攤位整理表單! 以下表格將跟各位講解有關如何使用此整理表單。如果沒有問題，可直接至「攤位整理表單 請在此填寫資料」試算表中填寫喔! 我們並非開拓官方，請注意。 | K4: 攤位位置 (我們已幫您填寫，若有誤請跟我們連繫) | N4: 攤主基本資訊 | P4: 販售詳細資訊 | W4: 網頁/社群網站SNS | AQ4: 本次販售資訊連結及賣場 | AU4: 呈現在攤位查詢網上的縮圖 | AW4: 本次販售資訊連結及賣場
B7: 表單結構 | C7: 攤位位置 | D7: 包含攤位編號、分區等，我們已經幫您導入了
I8: 表1, 攤位整理表單格式
C9: 攤主基本資訊 | D9: 包含您的筆名、創作者類型，創作者類型請見右表2，可自訂
C10: 販售詳細資訊 | D10: 年齡分級 (一般，R15，R18)，可複選 | I10: 表2. 創作者類型
D11: 作品類型 (原創? 二創?)。如果是二創，那麼二創的參考作品? (如蔚藍檔案等) | I11: 繪師 | J11: Coser | K11: Vtuber | L11: 寫手/作家 | M11: 音聲作品
I12: 模型製作 | J12: 代理社團 | K12: 手工藝品 | L12: 攝影相關 | M12: 遊戲作品
D13: 販售資訊，請列出你想要賣甚麼? 如同人誌、立牌、飯友等，可於商品後面標示價格。 | I13: 學生社團 | J13: Vtype
D14: 特殊標籤，如有特殊癖好如扶他、獸人、性轉，或是要標註男性女性向等，可列出 | I14: 整理進度說明
D15: 場前印調，場前印調部分就跟SNS的方式一樣，備註表單連結即可
C16: 社群網站連結 | D16: 您的社團、個人、品牌社群網站連結，詳細請見表1。填寫時，請填寫有效之網址，如果為多網址，請空一格後，將網址貼進來，不可在網址欄中加入非網址之文字，不然系統會無法識別而沒有更新。 | I16: 本次攤位整理新增區域 以下區域權限全面開放，不需使用加註功能
C17: 本次販售資訊連結 | D17: 請貼上您的預告、品書連結、預購通販、賣場、試閱連結 | I17: 集中宣傳區 | J17: 如果攤主要宣傳自家的周邊，可至此處進行宣傳喔
C18: 縮圖 | D18: 請貼上您打算在我們攤位查詢網中呈現的縮圖 Google 雲端連結 | I18: 印量調查區 | J18: 如果攤主要針對產品的印製數量進行調查，可至此處進行印調，印調的網址將會同步在攤位整理表中
D19: 格式: 橫式、尺寸 2:1，解析度至少 800x400px，檔案需使用Google雲端連結提供，並且需開共享。縮圖不可以瑟瑟! | I19: 交流區 | J19: 無論參加者還是攤主，都可以聊天交流之處
B21: 加 註 功 能 詳 細 使 用 教 學 | I21: 因徵求寄攤區可能會被開拓方監控，為避免起爭議，本屆暫停提供徵求寄攤區
B23: 一、如何使用註解/加註功能 | I23: 攤位整理不容易，歡迎贊助支持我們! :D
B24: 如何打開加註功能? 電腦版教學
I25: 其他場次的簡易攤位整理
I26: 贊助合作宣傳，讓加帕利幫你宣傳你的攤位資訊
I29: 距離開場 | J29: 46255.438 | M29: 剩下 | N29: =INT(J29 - J30) & " 日 " & HOUR(J29 - J30) & " 時 " & MINUTE(J29 - J30) & " 分 " & SECOND(J29 - J30) & " 秒 " -> 9 日 18 時 54 分 23 秒
I30: 現在時間 | J30: =NOW() -> 46245.65
C34: 第一步: 先選擇你想要填寫的格子，點選它 | F34: 點選左上角的「插入註解」也可達成相同效果喔
C35: 第二步: 按滑鼠右鍵，把選單叫出來
C36: 第三步: 點選「註解」
C37: 第四步: 此時便可填寫您的資料
B38: 如何打開加註功能? 手機版教學
J53: 你的測試地點 | K53: 上圖1. 成功叫出註解框的樣子
I54: 測試方格-->
I55: 您可以在上面方塊測試註解
C58: 第一步: 點選您要填寫的格子 | K58: 上圖2. 註解成功輸出的畫面
C59: 第二步: 點選右下角的「對話框」
C60: 第三步: 輸入註解
C61: 各位可至右上邊的測試欄位試試看喔!
B62: 二、資料填寫
B63: 假設今天有一個攤主要填寫資料，其資料如下表所示 (然後想在周日寄攤) | F63: 填寫步驟
F64: 第一步: 使用「CTRL+F」功能，尋找您的攤位 (手機請使用「尋找並取代」功能)
F67: 第二步: 進入到我們的攤位整理表單中
F69: 第三步: 使用「註解/加註」功能，將資料註解上去，填寫方式如右表4示範所示
F72: 第四步: 等待攤位整理人員將您的註解資料填寫上去
...

Sheet 攤位整理表 請在此填寫資訊
A1: 攤位名稱 | B1: 筆名 | C1: 第一天 | D1: 第二天 | E1: 第三天 | G1: 創作者類型 | H1: 商品年齡分類 | I1: 作品類型 (原創、二創) | J1: 二創參考作品 (原創免填) | K1: 販售資訊 | L1: 特殊標籤或備註 | M1: {={ "有無資料"; BYROW(S2:AM1337, LAMBDA(currRow, COUNTA(currRow)>0)) }} -> 有無資料 | N1: {={ "有無販售資訊"; BYROW(H2:L1337, LAMBDA(currRow,COUNTA(currRow)>0)) }} -> 有無販售資訊 | O1: {={"有無預告";MAP(AN2:AN1337, LAMBDA(cell, ISTEXT(cell)))}} -> 有無預告 | P1: {={"有無品書";MAP(AO2:AO1337, LAMBDA(cell, ISTEXT(cell)))}} -> 有無品書 | Q1: 資料信心度 | R1: 印量調查 請至印調區填寫 | S1: FB (1) | T1: FB (2) | U1: Bluesky (1) | V1: Bluesky (2) | W1: TWITTER (1) | X1: TWITTER (2) | Y1: PLURK | Z1: Pixiv | AA1: Fanbox | AB1: Fantia | AC1: 可洛斯 | AD1: 其他贊助平台 | AE1: IG | AF1: YOUTUBE | AG1: TWITCH | AH1: LINE | AI1: DISCORD | AJ1: 巴哈姆特 | AK1: 官方網站 | AL1: Linktree等連結整合網頁 | AM1: 其他連結 | AN1: 預告 | AO1: 品書 | AP1: 預購/通販 | AQ1: 縮圖[請備註] | AR1: 是否有縮圖 | AS1: 試閱
A2: 2.5 | E2: U43 | M2: FALSE | N2: FALSE | O2: FALSE | P2: FALSE | R2: {=IFERROR(INDEX('印量調查區'!G:G, MATCH(A2, '印量調查區'!A:A, 0)), "")} | AR2: =IFERROR(__xludf.DUMMYFUNCTION("IF(IFERROR(VLOOKUP(A2, IMPORTRANGE(""https://docs.google.com/spreadsheets/d/1f7uHQQgxgff8nh6aFDrh_cqkeFpcVPsvJILesm778_0"", ""工作表1!A:B""), 2, FALSE), """") <> """", ""有縮圖"", ""無縮圖"")"),"無縮圖") -> 無縮圖
A3: 825 | D3: T08 | G3: Coser | M3: FALSE | N3: FALSE | O3: FALSE | P3: FALSE | R3: {=IFERROR(INDEX('印量調查區'!G:G, MATCH(A3, '印量調查區'!A:A, 0)), "")} | AR3: =IFERROR(__xludf.DUMMYFUNCTION("IF(IFERROR(VLOOKUP(A3, IMPORTRANGE(""https://docs.google.com/spreadsheets/d/1f7uHQQgxgff8nh6aFDrh_cqkeFpcVPsvJILesm778_0"", ""工作表1!A:B""), 2, FALSE), """") <> """", ""有縮圖"", ""無縮圖"")"),"無縮圖") -> 無縮圖
A4: ‘-Sakimiya- | B4: 校工 | D4: N03 | G4: 繪師 | I4: 二創 | J4: 蔚藍檔案 / Blue Archive / ブルーアーカイブ | M4: TRUE | N4: TRUE | O4: FALSE | P4: FALSE | R4: {=IFERROR(INDEX('印量調查區'!G:G, MATCH(A4, '印量調查區'!A:A, 0)), "")} | W4: https://x.com/sakimiya_Hsu?t=jSZ9U8yrx9KsiNHAgOo6Iw&s=09 | Y4: https://www.plurk.com/sakimiya | Z4: https://www.pixiv.net/users/3029076 | AJ4: https://home.gamer.com.tw/profile/index.php?owner=p30000909120 | AL4: https://lit.link/zh-tw/sakimiyaHsu | AM4: https://skeb.jp/@sakimiya_Hsu | AR4: =IFERROR(__xludf.DUMMYFUNCTION("IF(IFERROR(VLOOKUP(A4, IMPORTRANGE(""https://docs.google.com/spreadsheets/d/1f7uHQQgxgff8nh6aFDrh_cqkeFpcVPsvJILesm778_0"", ""工作表1!A:B""), 2, FALSE), """") <> """", ""有縮圖"", ""無縮圖"")"),"無縮圖") -> 無縮圖
A5: [CHOCOLATE SHOP] | B5: CHOCO | C5: E19,E20 | D5: E19,E20 | G5: 繪師 | M5: TRUE | N5: FALSE | O5: FALSE | P5: FALSE | R5: {=IFERROR(INDEX('印量調查區'!G:G, MATCH(A5, '印量調查區'!A:A, 0)), "")} | W5: https://x.com/chocolateshop_i | Z5: https://www.pixiv.net/users/4768145 | AR5: =IFERROR(__xludf.DUMMYFUNCTION("IF(IFERROR(VLOOKUP(A5, IMPORTRANGE(""https://docs.google.com/spreadsheets/d/1f7uHQQgxgff8nh6aFDrh_cqkeFpcVPsvJILesm778_0"", ""工作表1!A:B""), 2, FALSE), """") <> """", ""有縮圖"", ""無縮圖"")"),"無縮圖") -> 無縮圖
A6: 【ZENTENG】 | E6: F02 | G6: 繪師 | M6: TRUE | N6: FALSE | O6: FALSE | P6: FALSE | R6: {=IFERROR(INDEX('印量調查區'!G:G, MATCH(A6, '印量調查區'!A:A, 0)), "")} | S6: https://www.facebook.com/Zen-Teng-214385615977145/ | AR6: =IFERROR(__xludf.DUMMYFUNCTION("IF(IFERROR(VLOOKUP(A6, IMPORTRANGE(""https://docs.google.com/spreadsheets/d/1f7uHQQgxgff8nh6aFDrh_cqkeFpcVPsvJILesm778_0"", ""工作表1!A:B""), 2, FALSE), """") <> """", ""有縮圖"", ""無縮圖"")"),"無縮圖") -> 無縮圖
A7: #DREAMProject [JooA Cosplay] | D7: Q23,Q24 | E7: Q23,Q24 | G7: Coser | M7: TRUE | N7: FALSE | O7: FALSE | P7: FALSE | R7: {=IFERROR(INDEX('印量調查區'!G:G, MATCH(A7, '印量調查區'!A:A, 0)), "")} | S7: https://www.facebook.com/dreamproject0079/?locale=zh_TW | AR7: =IFERROR(__xludf.DUMMYFUNCTION("IF(IFERROR(VLOOKUP(A7, IMPORTRANGE(""https://docs.google.com/spreadsheets/d/1f7uHQQgxgff8nh6aFDrh_cqkeFpcVPsvJILesm778_0"", ""工作表1!A:B""), 2, FALSE), """") <> """", ""有縮圖"", ""無縮圖"")"),"無縮圖") -> 無縮圖
A8: #DREAMProject Momo | B8: 毛毛 | D8: R39 | E8: R39 | G8: Coser | M8: TRUE | N8: FALSE | O8: FALSE | P8: FALSE | R8: {=IFERROR(INDEX('印量調查區'!G:G, MATCH(A8, '印量調查區'!A:A, 0)), "")} | S8: https://www.facebook.com/lovemolove | W8: https://twitter.com/lovemomosweet | AB8: https://fantia.jp/fanclubs/52892?locale=zh-tw | AE8: https://www.instagram.com/momo180_cos/ | AG8: https://www.twitch.tv/lovemomosweet | AL8: https://linktr.ee/lovemomosweet?utm_source=linktree_profile_share&ltsid=db415409-4786-4a29-a547-9cfc4302406b | AR8: =IFERROR(__xludf.DUMMYFUNCTION("IF(IFERROR(VLOOKUP(A8, IMPORTRANGE(""https://docs.google.com/spreadsheets/d/1f7uHQQgxgff8nh6aFDrh_cqkeFpcVPsvJILesm778_0"", ""工作表1!A:B""), 2, FALSE), """") <> """", ""有縮圖"", ""無縮圖"")"),"無縮圖") -> 無縮圖
A9: #DREAMProject Neneko | B9: 肉肉 | D9: R43,R44 | E9: R43,R44 | G9: Coser | M9: TRUE | N9: FALSE | O9: FALSE | P9: FALSE | R9: {=IFERROR(INDEX('印量調查區'!G:G, MATCH(A9, '印量調查區'!A:A, 0)), "")} | S9: https://www.facebook.com/neneko.page?locale=zh_TW | AR9: =IFERROR(__xludf.DUMMYFUNCTION("IF(IFERROR(VLOOKUP(A9, IMPORTRANGE(""https://docs.google.com/spreadsheets/d/1f7uHQQgxgff8nh6aFDrh_cqkeFpcVPsvJILesm778_0"", ""工作表1!A:B""), 2, FALSE), """") <> """", ""有縮圖"", ""無縮圖"")"),"無縮圖") -> 無縮圖
A10: #DREAMProject Shimo | B10: 霜月 | D10: R40,R41 | E10: R40,R41 | G10: Coser | K10: 寫真集 一番賞 現場拍立得 | M10: TRUE | N10: TRUE | O10: FALSE | P10: FALSE | R10: {=IFERROR(INDEX('印量調查區'!G:G, MATCH(A10, '印量調查區'!A:A, 0)), "")} | S10: https://www.facebook.com/shimotsuki18 | AR10: =IFERROR(__xludf.DUMMYFUNCTION("IF(IFERROR(VLOOKUP(A10, IMPORTRANGE(""https://docs.google.com/spreadsheets/d/1f7uHQQgxgff8nh6aFDrh_cqkeFpcVPsvJILesm778_0"", ""工作表1!A:B""), 2, FALSE), """") <> """", ""有縮圖"", ""無縮圖"")"),"無縮圖") -> 無縮圖
A11: #DREAMProject Usagi羽咲 | B11: 羽咲 | C11: Q02 [寄] | D11: R42 | E11: R42 | G11: Coser | H11: 一般 | I11: 二創 | J11: 蔚藍檔案 / Blue Archive / ブルーアーカイブ，百合園聖亞，紫羅蘭永恆花園 | K11: 聖亞套組 1-6 1500元 💠1、聖亞寫真集 600元 💠2、坐姿立牌 💠3、折疊圓鏡 💠4、貼紙組 100元 💠5、寫真照 200元 💠6、應援扇 200元 | M11: TRUE | N11: TRUE | O11: TRUE | P11: TRUE | R11: {=IFERROR(INDEX('印量調查區'!G:G, MATCH(A11, '印量調查區'!A:A, 0)), "")} | S11: https://www.facebook.com/UsagiTW | W11: https://twitter.com/Usagi__tw?t=ixuelpbn0R8uq7N9PL3bNg&s=09 | AE11: https://www.instagram.com/usagi_tw?utm_source=ig_web_button_share_sheet&igsh=ZDNlZDc0MzIxNw== | AN11: https://www.facebook.com/UsagiTW/posts/pfbid027P1pNzny93BpfJkRchjWgugGtUMV4JvQWj7vtkXJQyJ8AphQzBDdP3zwHhKtCD6rl https://www.facebook.com/100063575087204/posts/pfbid02ipi5ygnReXxwLB1yycyottdqReWTaFeKN8zYGWxxME3YynUdHsy8aXCH8NVWY3K4l/? https://www.facebook.com/UsagiTW/posts/pfbid02VK8d1bsnWPE1dELMHov3o96cUDd1AYJQjdsruEgdVfuH9ZGctCaEYTb6r4prz88yl | AO11: https://www.facebook.com/photo.php?fbid=1680506590745161&set=p.1680506590745161&type=3 | AP11: https://reurl.cc/dOWj6g | AR11: =IFERROR(__xludf.DUMMYFUNCTION("IF(IFERROR(VLOOKUP(A11, IMPORTRANGE(""https://docs.google.com/spreadsheets/d/1f7uHQQgxgff8nh6aFDrh_cqkeFpcVPsvJILesm778_0"", ""工作表1!A:B""), 2, FALSE), """") <> """", ""有縮圖"", ""無縮圖"")"),"無縮圖") -> 無縮圖
A12: +喵耳園魔法道具屋+ | G12: 手工藝品 | M12: TRUE | N12: FALSE | O12: FALSE | P12: FALSE | R12: {=IFERROR(INDEX('印量調查區'!G:G, MATCH(A12, '印量調查區'!A:A, 0)), "")} | AE12: https://www.instagram.com/cat_ears2007/ | AR12: =IFERROR(__xludf.DUMMYFUNCTION("IF(IFERROR(VLOOKUP(A12, IMPORTRANGE(""https://docs.google.com/spreadsheets/d/1f7uHQQgxgff8nh6aFDrh_cqkeFpcVPsvJILesm778_0"", ""工作表1!A:B""), 2, FALSE), """") <> """", ""有縮圖"", ""無縮圖"")"),"無縮圖") -> 無縮圖
A13: +Ely Cosplay+ | B13: Ely | G13: Coser | M13: TRUE | N13: FALSE | O13: FALSE | P13: FALSE | R13: {=IFERROR(INDEX('印量調查區'!G:G, MATCH(A13, '印量調查區'!A:A, 0)), "")} | S13: https://www.facebook.com/eeelyeee/ | W13: https://twitter.com/Ely_eee | AE13: IG | AR13: =IFERROR(__xludf.DUMMYFUNCTION("IF(IFERROR(VLOOKUP(A13, IMPORTRANGE(""https://docs.google.com/spreadsheets/d/1f7uHQQgxgff8nh6aFDrh_cqkeFpcVPsvJILesm778_0"", ""工作表1!A:B""), 2, FALSE), """") <> """", ""有縮圖"", ""無縮圖"")"),"無縮圖") -> 無縮圖
A14: ＋そおの | D14: H18 | E14: H17,H18 | G14: 繪師 | M14: TRUE | N14: FALSE | O14: FALSE | P14: FALSE | R14: {=IFERROR(INDEX('印量調查區'!G:G, MATCH(A14, '印量調查區'!A:A, 0)), "")} | W14: https://x.com/soOno2020 | Z14: https://www.pixiv.net/users/540668 | AE14: https://www.instagram.com/soono_artist | AF14: https://www.youtube.com/channel/UCJ4lUmPIs4RhEihsSZ7Jl1Q | AM14: https://soono.weebly.com/?utm_source=ig&utm_medium=social&utm_content=link_in_bio | AR14: =IFERROR(__xludf.DUMMYFUNCTION("IF(IFERROR(VLOOKUP(A14, IMPORTRANGE(""https://docs.google.com/spreadsheets/d/1f7uHQQgxgff8nh6aFDrh_cqkeFpcVPsvJILesm778_0"", ""工作表1!A:B""), 2, FALSE), """") <> """", ""有縮圖"", ""無縮圖"")"),"無縮圖") -> 無縮圖
A15: ～黑色布丁～ | D15: C44 | E15: C44 | G15: 繪師 | M15: TRUE | N15: FALSE | O15: FALSE | P15: FALSE | R15: {=IFERROR(INDEX('印量調查區'!G:G, MATCH(A15, '印量調查區'!A:A, 0)), "")} | S15: https://www.facebook.com/melanianpurin | Y15: https://www.plurk.com/melanianpruin | AR15: =IFERROR(__xludf.DUMMYFUNCTION("IF(IFERROR(VLOOKUP(A15, IMPORTRANGE(""https://docs.google.com/spreadsheets/d/1f7uHQQgxgff8nh6aFDrh_cqkeFpcVPsvJILesm778_0"", ""工作表1!A:B""), 2, FALSE), """") <> """", ""有縮圖"", ""無縮圖"")"),"無縮圖") -> 無縮圖
A16: ～NEKONABE～ | E16: C43 | G16: 繪師 | I16: 二創 | J16: 精靈寶可夢 | M16: TRUE | N16: TRUE | O16: FALSE | P16: FALSE | R16: {=IFERROR(INDEX('印量調查區'!G:G, MATCH(A16, '印量調查區'!A:A, 0)), "")} | S16: https://www.facebook.com/profile.php?id=100066562821753 | AR16: =IFERROR(__xludf.DUMMYFUNCTION("IF(IFERROR(VLOOKUP(A16, IMPORTRANGE(""https://docs.google.com/spreadsheets/d/1f7uHQQgxgff8nh6aFDrh_cqkeFpcVPsvJILesm778_0"", ""工作表1!A:B""), 2, FALSE), """") <> """", ""有縮圖"", ""無縮圖"")"),"無縮圖") -> 無縮圖
A17: ♡可凡kofan0331 | B17: 可凡 | C17: R37,R38 | D17: R37,R38 | G17: Coser | M17: TRUE | N17: FALSE | O17: FALSE | P17: FALSE | R17: {=IFERROR(INDEX('印量調查區'!G:G, MATCH(A17, '印量調查區'!A:A, 0)), "")} | S17: https://m.facebook.com/kofan331/ | W17: https://twitter.com/kofan0331/status/1552294307767341058?s=46&t=BBl9xiG-s1NqApoWBm401g | AD17: https://www.patreon.com/kofan0331 https://streamlabs.com/kofan0331/tip | AE17: https://www.instagram.com/kofan_0331/?hl=zh-tw | AF17: https://youtube.com/c/kofan%E5%8F%AF%E5%87%A1 | AG17: https://m.twitch.tv/kofan0331 | AI17: https://discord.gg/f9ukYFb | AL17: https://taplink.cc/kofan_0331?fbclid=PAZXh0bgNhZW0CMTEAAactAAtQW-I09r3QO7QEZFi7BONssX6zyCvfLKDLBZMNczkOUmn6UlXnuB9-fQ_aem_0Yfbze5olK5vRZAtJUqXEw | AR17: =IFERROR(__xludf.DUMMYFUNCTION("IF(IFERROR(VLOOKUP(A17, IMPORTRANGE(""https://docs.google.com/spreadsheets/d/1f7uHQQgxgff8nh6aFDrh_cqkeFpcVPsvJILesm778_0"", ""工作表1!A:B""), 2, FALSE), """") <> """", ""有縮圖"", ""無縮圖"")"),"無縮圖") -> 無縮圖
A18: 0蛋黃女子由奈0 | D18: R07 | E18: R07 | G18: Coser | M18: TRUE | N18: FALSE | O18: FALSE | P18: FALSE | R18: {=IFERROR(INDEX('印量調查區'!G:G, MATCH(A18, '印量調查區'!A:A, 0)), "")} | S18: https://www.facebook.com/matsuokayune.2015/ | AE18: https://www.instagram.com/akai_yuna_1110/ | AL18: https://linktr.ee/matsuoka_yuna | AR18: =IFERROR(__xludf.DUMMYFUNCTION("IF(IFERROR(VLOOKUP(A18, IMPORTRANGE(""https://docs.google.com/spreadsheets/d/1f7uHQQgxgff8nh6aFDrh_cqkeFpcVPsvJILesm778_0"", ""工作表1!A:B""), 2, FALSE), """") <> """", ""有縮圖"", ""無縮圖"")"),"無縮圖") -> 無縮圖
A19: 1%小風 | B19: 小風 | C19: B10 | G19: 繪師 | I19: 二創 | J19: Hololive | M19: TRUE | N19: TRUE | O19: FALSE | P19: FALSE | R19: {=IFERROR(INDEX('印量調查區'!G:G, MATCH(A19, '印量調查區'!A:A, 0)), "")} | S19: https://www.facebook.com/FFFfengXX/?locale=zh_TW | AR19: =IFERROR(__xludf.DUMMYFUNCTION("IF(IFERROR(VLOOKUP(A19, IMPORTRANGE(""https://docs.google.com/spreadsheets/d/1f7uHQQgxgff8nh6aFDrh_cqkeFpcVPsvJILesm778_0"", ""工作表1!A:B""), 2, FALSE), """") <> """", ""有縮圖"", ""無縮圖"")"),"無縮圖") -> 無縮圖
A20: 23.4ド＆きのこのみ＆蜂蜜少女 | B20: イチリ, きのこのみ, 蜜桃まむ | D20: G34 | G20: 繪師，日本 | I20: 二創 | J20: 請問您今天要來點兔子嗎? / Is the order a rabbit? / ご注文はうさぎですか?? | M20: TRUE | N20: TRUE | O20: FALSE | P20: FALSE | R20: {=IFERROR(INDEX('印量調查區'!G:G, MATCH(A20, '印量調查區'!A:A, 0)), "")} | W20: https://x.com/234itiri | X20: https://x.com/mamgon | AA20: https://mamgon.fanbox.cc/ | AB20: https://itiri.fanbox.cc/ | AR20: =IFERROR(__xludf.DUMMYFUNCTION("IF(IFERROR(VLOOKUP(A20, IMPORTRANGE(""https://docs.google.com/spreadsheets/d/1f7uHQQgxgff8nh6aFDrh_cqkeFpcVPsvJILesm778_0"", ""工作表1!A:B""), 2, FALSE), """") <> """", ""有縮圖"", ""無縮圖"")"),"無縮圖") -> 無縮圖
A21: 33号部屋 | B21: 微雨 | C21: O25 | D21: O25 | G21: 繪師 | I21: 二創 | J21: 蔚藍檔案 / Blue Archive / ブルーアーカイブ | M21: TRUE | N21: TRUE | O21: TRUE | P21: FALSE | R21: {=IFERROR(INDEX('印量調查區'!G:G, MATCH(A21, '印量調查區'!A:A, 0)), "")} | S21: https://facebook.com/yu.yan.ting.974906/ | W21: https://twitter.com/Yen_Ting_Yu | Y21: https://www.plurk.com/rifrif686 | Z21: https://www.pixiv.net/users/3433634 | AN21: https://www.facebook.com/permalink.php?story_fbid=pfbid0Sjbto9HFM3mf1XkkoaT4DxFzDDT9d1Wu2dn5SoNYhJ6U7GKymBXdxBpFX6bYz5w3l&id=61583891031404 | AR21: =IFERROR(__xludf.DUMMYFUNCTION("IF(IFERROR(VLOOKUP(A21, IMPORTRANGE(""https://docs.google.com/spreadsheets/d/1f7uHQQgxgff8nh6aFDrh_cqkeFpcVPsvJILesm778_0"", ""工作表1!A:B""), 2, FALSE), """") <> """", ""有縮圖"", ""無縮圖"")"),"有縮圖") -> 有縮圖
A22: 404便利通販 | B22: 熊初末 | C22: C06 | E22: B33 | G22: 繪師 | H22: 一般 | I22: 二創 | J22: 米哈遊 | K22: 音擎鑰匙圈盲盒 (伸縮鑰匙圈) 壓克力立牌 簽繪板 掛軸 | M22: TRUE | N22: TRUE | O22: TRUE | P22: TRUE | R22: {=IFERROR(INDEX('印量調查區'!G:G, MATCH(A22, '印量調查區'!A:A, 0)), "")} | S22: https://www.facebook.com/404Armory/ | T22: https://www.facebook.com/xiongchumo | U22: https://bsky.app/profile/beardad85414.bsky.social | W22: https://x.com/beardad85414 | Z22: https://www.pixiv.net/users/11526704 | AE22: https://www.instagram.com/beardad850414 | AM22: https://portaly.cc/beardad85414 | AN22: https://www.facebook.com/reel/3367086716832008/ | AO22: https://drive.google.com/file/d/1msQmu0U2Wo6IC-leRgMdwigybkSJegHq/view?usp=sharing | AR22: =IFERROR(__xludf.DUMMYFUNCTION("IF(IFERROR(VLOOKUP(A22, IMPORTRANGE(""https://docs.google.com/spreadsheets/d/1f7uHQQgxgff8nh6aFDrh_cqkeFpcVPsvJILesm778_0"", ""工作表1!A:B""), 2, FALSE), """") <> """", ""有縮圖"", ""無縮圖"")"),"無縮圖") -> 無縮圖
A23: 44c_isaac | C23: D35 | E23: D23 | G23: 繪師 | M23: TRUE | N23: FALSE | O23: TRUE | P23: FALSE | R23: {=IFERROR(INDEX('印量調查區'!G:G, MATCH(A23, '印量調查區'!A:A, 0)), "")} | W23: https://x.com/44c_isaac?lang=zh-TW | Z23: https://www.pixiv.net/users/19063155 | AJ23: https://home.gamer.com.tw/profile/index_feed.php?owner=lowkey0820 | AM23: https://weibo.com/isaacyeh | AN23: https://www.facebook.com/ssd.ada.831152/posts/pfbid02m47QRGEYFp9u1eVe7tT2K7PU27X1BmoWALE3Z8m4rDeSDYrJwMnHrSiLTEoTMvYyl | AR23: =IFERROR(__xludf.DUMMYFUNCTION("IF(IFERROR(VLOOKUP(A23, IMPORTRANGE(""https://docs.google.com/spreadsheets/d/1f7uHQQgxgff8nh6aFDrh_cqkeFpcVPsvJILesm778_0"", ""工作表1!A:B""), 2, FALSE), """") <> """", ""有縮圖"", ""無縮圖"")"),"無縮圖") -> 無縮圖
A24: 5年目の放課後 | D24: F26 | G24: 繪師 | M24: TRUE | N24: FALSE | O24: FALSE | P24: FALSE | R24: {=IFERROR(INDEX('印量調查區'!G:G, MATCH(A24, '印量調查區'!A:A, 0)), "")} | W24: https://twitter.com/kantoku_5th | Z24: https://www.pixiv.net/users/1565632 | AK24: http://5-y.2-d.jp/ | AR24: =IFERROR(__xludf.DUMMYFUNCTION("IF(IFERROR(VLOOKUP(A24, IMPORTRANGE(""https://docs.google.com/spreadsheets/d/1f7uHQQgxgff8nh6aFDrh_cqkeFpcVPsvJILesm778_0"", ""工作表1!A:B""), 2, FALSE), """") <> """", ""有縮圖"", ""無縮圖"")"),"無縮圖") -> 無縮圖
A25: 74 Production | D25: L06 | G25: 繪師 | M25: TRUE | N25: FALSE | O25: TRUE | P25: FALSE | R25: {=IFERROR(INDEX('印量調查區'!G:G, MATCH(A25, '印量調查區'!A:A, 0)), "")} | S25: https://www.facebook.com/IdolProduction74 | T25: https://www.facebook.com/profile.php?id=100000297013388 | W25: https://x.com/mikoair | Y25: https://www.plurk.com/summerair | Z25: https://www.pixiv.net/users/495657 | AN25: https://www.facebook.com/IdolProduction74/posts/pfbid02FhecfsRJSxCTJWm5cuYZaj6jmKad9c5WTMshwCS5rAKfcqBX6xWn8oB6KdbUvirql | AR25: =IFERROR(__xludf.DUMMYFUNCTION("IF(IFERROR(VLOOKUP(A25, IMPORTRANGE(""https://docs.google.com/spreadsheets/d/1f7uHQQgxgff8nh6aFDrh_cqkeFpcVPsvJILesm778_0"", ""工作表1!A:B""), 2, FALSE), """") <> """", ""有縮圖"", ""無縮圖"")"),"有縮圖") -> 有縮圖
A26: 7B鉛筆 | E26: A14 | M26: FALSE | N26: FALSE | O26: FALSE | P26: FALSE | R26: {=IFERROR(INDEX('印量調查區'!G:G, MATCH(A26, '印量調查區'!A:A, 0)), "")} | AR26: =IFERROR(__xludf.DUMMYFUNCTION("IF(IFERROR(VLOOKUP(A26, IMPORTRANGE(""https://docs.google.com/spreadsheets/d/1f7uHQQgxgff8nh6aFDrh_cqkeFpcVPsvJILesm778_0"", ""工作表1!A:B""), 2, FALSE), """") <> """", ""有縮圖"", ""無縮圖"")"),"無縮圖") -> 無縮圖
A27: 8七兔 | B27: 8七兔 | C27: D26 | G27: 繪師 | H27: 一般 | I27: 二創, 原創 | J27: Hololive，Ina，Vtuber，Saba，Gura | K27: 新刊套組 500元 💠1、同人誌新刊【Kaleidoscope】200元 💠2、壓克力立繪板 💠3、Ina奶飲料杯套 💠4、透明貼紙2張 150元 其他品項 💠Ina、Saba 壓克力飯友 200元 💠明信片 50元 既品 💠同人誌既刊 150元 💠胸章 150元/組 💠眼鏡布 100元 💠2026便當月曆 100元 💠Saba立牌 250元 💠吊飾 100元/個 250元/3個 💠滑鼠墊 150元 💠立繪板 200元 | M27: TRUE | N27: TRUE | O27: FALSE | P27: TRUE | R27: {=IFERROR(INDEX('印量調查區'!G:G, MATCH(A27, '印量調查區'!A:A, 0)), "")} | S27: https://www.facebook.com/profile.php?id=100094134949022 | W27: https://twitter.com/8nana_usa | Z27: https://www.pixiv.net/users/13614957 | AE27: https://www.instagram.com/illustration_aku007/?fbclid=IwAR30XW9AaLfNNg3gSXARaZv2zi_41q_XhrjNEtM7bCinFjthZ0Skr1h9TUQ | AO27: https://www.facebook.com/wu.zhu.ying.361685/posts/pfbid02bPyqHFMPbjeXnvqjJeFPfTWrwayuZQDeGcKcxWwRchKZhUkUxvyqnm6Ck5LEWMW6l | AP27: https://reurl.cc/vG52kA | AR27: =IFERROR(__xludf.DUMMYFUNCTION("IF(IFERROR(VLOOKUP(A27, IMPORTRANGE(""https://docs.google.com/spreadsheets/d/1f7uHQQgxgff8nh6aFDrh_cqkeFpcVPsvJILesm778_0"", ""工作表1!A:B""), 2, FALSE), """") <> """", ""有縮圖"", ""無縮圖"")"),"無縮圖") -> 無縮圖
A28: 一心三惑 | B28: とうち,桃李タロ | C28: L07,L08 | E28: L03,L04 | G28: 繪師 | M28: TRUE | N28: FALSE | O28: TRUE | P28: FALSE | R28: {=IFERROR(INDEX('印量調查區'!G:G, MATCH(A28, '印量調查區'!A:A, 0)), "")} | S28: https://www.facebook.com/misconception2014/ | W28: https://twitter.com/tori_mcct | Y28: PLURK | Z28: https://www.pixiv.net/users/14368479 | AN28: https://www.facebook.com/tc.chan.675349/posts/pfbid0oYUxjbDYvHQSZaauX7XmztPxDVUqGpZLfrpYknX1QqZyigU4yAaARQT6xKt7deG5l | AR28: =IFERROR(__xludf.DUMMYFUNCTION("IF(IFERROR(VLOOKUP(A28, IMPORTRANGE(""https://docs.google.com/spreadsheets/d/1f7uHQQgxgff8nh6aFDrh_cqkeFpcVPsvJILesm778_0"", ""工作表1!A:B""), 2, FALSE), """") <> """", ""有縮圖"", ""無縮圖"")"),"無縮圖") -> 無縮圖
A29: 一米七雪貓 | B29: 雪貓 | C29: B15,B16 | D29: B15,B16 | G29: 繪師，Coser | M29: TRUE | N29: FALSE | O29: FALSE | P29: FALSE | R29: {=IFERROR(INDEX('印量調查區'!G:G, MATCH(A29, '印量調查區'!A:A, 0)), "")} | S29: https://www.facebook.com/yukineko170 | T29: https://www.facebook.com/seaoceanumi | U29: https://bsky.app/profile/yukineko0975.bsky.social | W29: https://x.com/yukineko0975 | X29: https://x.com/yukineko097 | Z29: https://www.pixiv.net/users/25447095 | AA29: https://yukineko0975.fanbox.cc/ | AE29: https://www.instagram.com/yukineko170/ | AF29: https://www.youtube.com/@yukineko097 | AG29: https://www.twitch.tv/yukineko0975 | AI29: https://discord.com/invite/G5DUnS2Qcz | AJ29: https://m.gamer.com.tw/home/home.php?owner=yukineko1018 | AL29: https://linktr.ee/yukineko0975 | AR29: =IFERROR(__xludf.DUMMYFUNCTION("IF(IFERROR(VLOOKUP(A29, IMPORTRANGE(""https://docs.google.com/spreadsheets/d/1f7uHQQgxgff8nh6aFDrh_cqkeFpcVPsvJILesm778_0"", ""工作表1!A:B""), 2, FALSE), """") <> """", ""有縮圖"", ""無縮圖"")"),"無縮圖") -> 無縮圖
A30: 一虎虎虎 | C30: L44 | E30: L06 | G30: 繪師 | M30: TRUE | N30: FALSE | O30: FALSE | P30: FALSE | Q30: 高 | R30: {=IFERROR(INDEX('印量調查區'!G:G, MATCH(A30, '印量調查區'!A:A, 0)), "")} | S30: https://www.facebook.com/yihu15/ | W30: https://x.com/yihu_15 | AE30: https://www.instagram.com/yihu_15/ | AG30: https://www.twitch.tv/yihu15 | AL30: https://portaly.cc/yihu_15?utm_source=ig&utm_medium=social&utm_content=link_in_bio&fbclid=PAZXh0bgNhZW0CMTEAc3J0YwZhcHBfaWQPOTM2NjE5NzQzMzkyNDU5AAGnG7bfuIo7zfH0Y5o0j7ENjzeAkuDEqEXrOn1K4z25oTbXqMJVy8iq4-__SbQ_aem_3Dvr6XFLaV_4N_6KASU7MQ&utm_id=97760_v0_s00_e0_tv3 | AR30: =IFERROR(__xludf.DUMMYFUNCTION("IF(IFERROR(VLOOKUP(A30, IMPORTRANGE(""https://docs.google.com/spreadsheets/d/1f7uHQQgxgff8nh6aFDrh_cqkeFpcVPsvJILesm778_0"", ""工作表1!A:B""), 2, FALSE), """") <> """", ""有縮圖"", ""無縮圖"")"),"無縮圖") -> 無縮圖
A31: 一個小路人 | B31: 路人 | C31: J30 | G31: 繪師 | M31: TRUE | N31: FALSE | O31: FALSE | P31: FALSE | R31: {=IFERROR(INDEX('印量調查區'!G:G, MATCH(A31, '印量調查區'!A:A, 0)), "")} | S31: https://www.facebook.com/p/%E5%B0%8F%E8%B7%AF%E4%BA%BA%E7%9A%84%E8%85%A6%E6%B4%9E%E5%A1%97%E9%B4%89%E7%89%86-100077894957363/ | W31: https://x.com/Miga_Chen | Y31: https://www.plurk.com/s/u/susan1980735?offset= | AR31: =IFERROR(__xludf.DUMMYFUNCTION("IF(IFERROR(VLOOKUP(A31, IMPORTRANGE(""https://docs.google.com/spreadsheets/d/1f7uHQQgxgff8nh6aFDrh_cqkeFpcVPsvJILesm778_0"", ""工作表1!A:B""), 2, FALSE), """") <> """", ""有縮圖"", ""無縮圖"")"),"無縮圖") -> 無縮圖
A32: 一個簡單的黛黛 | E32: R13,R14 | G32: Coser | M32: FALSE | N32: FALSE | O32: FALSE | P32: FALSE | R32: {=IFERROR(INDEX('印量調查區'!G:G, MATCH(A32, '印量調查區'!A:A, 0)), "")} | AR32: =IFERROR(__xludf.DUMMYFUNCTION("IF(IFERROR(VLOOKUP(A32, IMPORTRANGE(""https://docs.google.com/spreadsheets/d/1f7uHQQgxgff8nh6aFDrh_cqkeFpcVPsvJILesm778_0"", ""工作表1!A:B""), 2, FALSE), """") <> """", ""有縮圖"", ""無縮圖"")"),"無縮圖") -> 無縮圖
A33: 一隻呆呆魚 | E33: D43,D44 | M33: FALSE | N33: FALSE | O33: FALSE | P33: FALSE | R33: {=IFERROR(INDEX('印量調查區'!G:G, MATCH(A33, '印量調查區'!A:A, 0)), "")} | AR33: =IFERROR(__xludf.DUMMYFUNCTION("IF(IFERROR(VLOOKUP(A33, IMPORTRANGE(""https://docs.google.com/spreadsheets/d/1f7uHQQgxgff8nh6aFDrh_cqkeFpcVPsvJILesm778_0"", ""工作表1!A:B""), 2, FALSE), """") <> """", ""有縮圖"", ""無縮圖"")"),"無縮圖") -> 無縮圖
A34: 一輩子少女樂團 | D34: U15 [寄] | E34: U13,U14 | G34: 繪師 | H34: 一般 | I34: 二創 | J34: Bang Dream，MyGO!!!!!，Ave Mujica，少女樂團吶喊吧 (女團哭 GBC)，孤獨搖滾 | K34: 壓克力雙面吊飾 100元 | M34: TRUE | N34: TRUE | O34: FALSE | P34: TRUE | R34: {=IFERROR(INDEX('印量調查區'!G:G, MATCH(A34, '印量調查區'!A:A, 0)), "")} | AM34: https://www.threads.com/@ry_rouyu | AO34: https://www.threads.com/@ry_rouyu/post/DbkhvDoidRn | AR34: =IFERROR(__xludf.DUMMYFUNCTION("IF(IFERROR(VLOOKUP(A34, IMPORTRANGE(""https://docs.google.com/spreadsheets/d/1f7uHQQgxgff8nh6aFDrh_cqkeFpcVPsvJILesm778_0"", ""工作表1!A:B""), 2, FALSE), """") <> """", ""有縮圖"", ""無縮圖"")"),"無縮圖") -> 無縮圖
A35: 一顆馬鈴薯-燦 | E35: G35 | G35: 繪師 | H35: 一般 | I35: 原創 | K35: 同人誌【馬鈴薯與他的快樂男人】 | M35: TRUE | N35: TRUE | O35: TRUE | P35: FALSE | R35: {=IFERROR(INDEX('印量調查區'!G:G, MATCH(A35, '印量調查區'!A:A, 0)), "")} | S35: https://www.facebook.com/lin.heng.166900/ | U35: https://bsky.app/profile/potato80501.bsky.social | Y35: https://www.plurk.com/potato80501 | AE35: https://www.instagram.com/potato80501in309/ | AM35: https://www.plurk.com/p/3izjsj05sc | AN35: https://www.plurk.com/p/3iy4ufnwxi | AR35: =IFERROR(__xludf.DUMMYFUNCTION("IF(IFERROR(VLOOKUP(A35, IMPORTRANGE(""https://docs.google.com/spreadsheets/d/1f7uHQQgxgff8nh6aFDrh_cqkeFpcVPsvJILesm778_0"", ""工作表1!A:B""), 2, FALSE), """") <> """", ""有縮圖"", ""無縮圖"")"),"無縮圖") -> 無縮圖
A36: 丁丁烤魚魚 | C36: J35,J36 | E36: L13,L14 | G36: 繪師 | M36: TRUE | N36: FALSE | O36: TRUE | P36: FALSE | R36: {=IFERROR(INDEX('印量調查區'!G:G, MATCH(A36, '印量調查區'!A:A, 0)), "")} | S36: https://www.facebook.com/shiyasakana/ | W36: https://twitter.com/shiyasakana | Y36: https://www.plurk.com/shiyasakana | AN36: https://x.com/shiyasakana/status/2060325475663405131 | AR36: =IFERROR(__xludf.DUMMYFUNCTION("IF(IFERROR(VLOOKUP(A36, IMPORTRANGE(""https://docs.google.com/spreadsheets/d/1f7uHQQgxgff8nh6aFDrh_cqkeFpcVPsvJILesm778_0"", ""工作表1!A:B""), 2, FALSE), """") <> """", ""有縮圖"", ""無縮圖"")"),"有縮圖") -> 有縮圖
A37: 丁丁dingding | C37: R14 | D37: R14 | G37: Coser | M37: TRUE | N37: FALSE | O37: FALSE | P37: FALSE | R37: {=IFERROR(INDEX('印量調查區'!G:G, MATCH(A37, '印量調查區'!A:A, 0)), "")} | S37: https://www.facebook.com/p/%E4%B8%81%E4%B8%81DingDing-100084623769863/ | W37: https://x.com/dingding_0106?fbclid=IwY2xjawSIzWRleHRuA2FlbQIxMABicmlkETFSS0NySzhvbnpSVWZQM0NRc3J0YwZhcHBfaWQQMjIyMDM5MTc4ODIwMDg5MgABHsE_h2zMx7jQCsr_SWDoCRiJHZI3DWVu9wLwaHb200PfdGDolf_g0koMHH3N_aem_D0LY30W7_lJBJStuHJ_qyA | AR37: =IFERROR(__xludf.DUMMYFUNCTION("IF(IFERROR(VLOOKUP(A37, IMPORTRANGE(""https://docs.google.com/spreadsheets/d/1f7uHQQgxgff8nh6aFDrh_cqkeFpcVPsvJILesm778_0"", ""工作表1!A:B""), 2, FALSE), """") <> """", ""有縮圖"", ""無縮圖"")"),"無縮圖") -> 無縮圖
A38: 七七小姐_Miss Seven | C38: R33,R34 | D38: R33,R34 | G38: Coser | M38: TRUE | N38: FALSE | O38: FALSE | P38: FALSE | R38: {=IFERROR(INDEX('印量調查區'!G:G, MATCH(A38, '印量調查區'!A:A, 0)), "")} | S38: https://www.facebook.com/Miss.double.seven/?locale=zh_TW | W38: https://x.com/coser_seven_tw | AE38: https://www.instagram.com/miss.seven.77/ | AF38: https://www.youtube.com/@seven5277 | AL38: https://linktr.ee/sevencosplay | AR38: =IFERROR(__xludf.DUMMYFUNCTION("IF(IFERROR(VLOOKUP(A38, IMPORTRANGE(""https://docs.google.com/spreadsheets/d/1f7uHQQgxgff8nh6aFDrh_cqkeFpcVPsvJILesm778_0"", ""工作表1!A:B""), 2, FALSE), """") <> """", ""有縮圖"", ""無縮圖"")"),"無縮圖") -> 無縮圖
A39: 七兔不好吃 | B39: 七兔 | D39: L33 | E39: M23,M24 | G39: Vtuber | H39: 一般 | M39: TRUE | N39: TRUE | O39: TRUE | P39: FALSE | R39: {=IFERROR(INDEX('印量調查區'!G:G, MATCH(A39, '印量調查區'!A:A, 0)), "")} | W39: https://x.com/Nayomi0204?ref_src=twsrc%5Egoogle%7Ctwcamp%5Eserp%7Ctwgr%5Eauthor | AG39: https://www.twitch.tv/nayomi0204 | AN39: https://x.com/nayomi0204/status/2081299581749575938?s=61&t=J9-H8xDVimG-T97w1or4FA https://www.instagram.com/p/DbbmvfJE6Jx/ | AR39: =IFERROR(__xludf.DUMMYFUNCTION("IF(IFERROR(VLOOKUP(A39, IMPORTRANGE(""https://docs.google.com/spreadsheets/d/1f7uHQQgxgff8nh6aFDrh_cqkeFpcVPsvJILesm778_0"", ""工作表1!A:B""), 2, FALSE), """") <> """", ""有縮圖"", ""無縮圖"")"),"無縮圖") -> 無縮圖
A40: 七叔神社 | B40: 七叔 | C40: B43 | G40: 繪師 | H40: 一般 | I40: 二創 | J40: 艦隊收藏 / Kantai Collection / 艦コレ | K40: 💠7公分壓克力立牌 120元，💠明信片 20元 | M40: TRUE | N40: TRUE | O40: FALSE | P40: TRUE | R40: {=IFERROR(INDEX('印量調查區'!G:G, MATCH(A40, '印量調查區'!A:A, 0)), "")} | S40: https://www.facebook.com/Uncle7Fansite/ | W40: https://x.com/nanaojisan | AF40: https://youtube.com/@nanaoji?si=zBfHFe1mH-wZFQHa | AO40: https://www.facebook.com/share/1Gs2pSrC11/?mibextid=wwXIfr | AR40: =IFERROR(__xludf.DUMMYFUNCTION("IF(IFERROR(VLOOKUP(A40, IMPORTRANGE(""https://docs.google.com/spreadsheets/d/1f7uHQQgxgff8nh6aFDrh_cqkeFpcVPsvJILesm778_0"", ""工作表1!A:B""), 2, FALSE), """") <> """", ""有縮圖"", ""無縮圖"")"),"有縮圖") -> 有縮圖
...

Sheet 集中宣傳區
A1: FF47 攤位集中宣傳區 (吃土單/宣傳串/廣告區)，歡迎攤主自行利用 [完成表單後，請協助在您的攤位欄位最底下拉底線，感謝]
A2: 攤位名稱 | B2: 天數 | C2: 攤位編號 | D2: 販售主題 | E2: 販售品項 | F2: 角色 / CP等 | G2: 售價 | H2: 品書/預告連結 | I2: 年齡分級 | J2: 特殊備註
A3: 加帕利天藍怪預警中心 [範例] | B3: 第二天 | C3: F22, F23 | D3: 點兔、蔚藍檔案、原創 [範例] | E3: 同人誌【xxxxxxxxx】 | F3: 心愛、智乃 | G3: 200 | H3: 預告 | I3: R18 | J3: 泡泡戀物癖
B4: 第三天 | C4: F23 | E4: 壓克力立牌 | F4: 智乃、冬優 | G4: 250 | H4: 品書 | I4: R15 | J4: [此為範例]
B5: 第二天 | C5: x | E5: 壓克力吊飾 | F5: 伊吹、原創 | G5: 150 | H5: [請在此放入連結] | I5: 一般
A6: 背骨貓屋 | B6: 第一天 | C6: W31、W32 | D6: 原創 鄰座的同學(們)怎麼有點奇怪 | E6: となおか新刊 | G6: NTD200 | H6: 通販 https://www.myacg.com.tw/seller_market.php?seller=551830 | I6: 一般
B7: 第二天 | C7: W31、W32 | E7: となおか新刊套組(插畫集『せぼあーと2』、雙面壓克力PP夾(4入)、 花奈醬姆指扇、不織布袋、明信片組三入) | F7: 花奈、貓山、砂糖 | G7: NTD600 | H7: 品書 https://www.facebook.com/share/p/1BkbZZrLDq// | I7: 一般
B8: 第三天 | C8: W31、W32 | E8: B2泳裝掛軸 (有三種款式) | F8: 花奈、貓山、砂糖 | G8: NTD600 | I8: 一般
A9: ACGN創作權益推動協會 | B9: 第一天 | C9: H34 | D9: 原創 | E9: ACGNMaker創刊號 | G9: 200 | H9: 預告：https://www.facebook.com/share/p/17t7488g78/ | I9: 一般
B10: 第二天 | C10: H34 | E10: 協會看板娘立牌 | G10: 150 | I10: 一般 | J10: 套組：300
A11: 秋森萬玩具店 | B11: 第一天 | C11: E08 | D11: 二創 | E11: 戰錘40k 獅王性轉同人本《別當哥哥了！但是在40k》(小黃雞老師) | F11: 戰錘40K 基因原體 獅王 萊恩 攝政王 基里曼 | G11: 350 | I11: 一般 | J11: 代理販售 全球限量 售完為止
E12: 戰錘40K 蘿伯特‧姬里蔓 金属書籤 (蟹仁飯老師) | G12: 400 | I12: 一般

Sheet 印量調查區
A1: 印量調查區，歡迎貼上貴攤位的印調資訊喔
A2: 您的攤位名稱 (需跟資料庫相同) | B2: 預計販售刊物/商品 | C2: 販售主題 | D2: 年齡分級 | E2: 刊物/商品簡介 | F2: 試閱連結 | G2: 印調連結
A3: 加帕利天藍怪預警中心 [範例] | B3: 同人誌【xxxx】、壓克力立牌 | C3: 點兔、蔚藍檔案 | D3: 一般, R18 | E3: xxxooooxxxx | F3: https://www.facebook.com/JapariWeatherBureau/posts/pfbid0sBU7c7iMXzyNrWzgnG4fgce7oo8JVx3N2oRjbi4cYrqscnTpbFHNGN3mREvfp89Ll | G3: https://www.facebook.com/JapariWeatherBureau/
A4: 星球蛋糕捲☆ | B4: T-Shirt | C4: Maimai | D4: 一般 | F4: https://www.facebook.com/share/p/18gS9cDbLt/?mibextid=wwXIfr | G4: https://forms.gle/ma1VC5NsLceRWKHeA
A5: 萬象澄澈 | B5: 同人誌【全年齡向原神本】 | C5: 原神 | D5: 一般 | E5: cp：洛恩x熒x葉洛亞/all熒（可嗑可代） | F5: https://www.plurk.com/p/3iwzaz0o46 | G5: https://forms.gle/PXowBJWWJhYe42Ud6
A6: SyuanIshen | B6: 同人誌、周邊 | C6: 九日 | D6: 一般, R18 | E6: CP：羿恆骨科 | F6: https://www.plurk.com/p/3iwjyyo30w | G6: https://docs.google.com/forms/d/e/1FAIpQLSd3MLMudawLu_L3bRP_1gD71TAsfvdbzGVRQ1t764WIv77Kzw/viewform
A7: 麥茶園 | B7: 飯友 | C7: 賽馬娘 | D7: 一般 | E7: 無聲鈴鹿 | F7: https://www.facebook.com/share/p/1D7BMk3e5M/ | G7: https://docs.google.com/forms/d/e/1FAIpQLScbxtqQ5_lSL1ytSo35TW5noX5KGbzJMVAyn_rZ6jkR-DNmfA/viewform?usp=dialog
A8: 邊緣小地方 | B8: 同人誌 | C8: 原創 | D8: R18 | E8: 雙頭龍X天使+惡魔的快樂瑟瑟3P | F8: https://www.doujin.com.tw/books/info/70374 | G8: https://forms.gle/Ktev8Lzxf36gfCHUA
A9: 茨城的繪圖小窩 | B9: 同人誌 | C9: 終末地,MyGO | D9: 一般 R18 | E9: 咕嘎騎士大戰爭 | F9: https://docs.google.com/forms/d/e/1FAIpQLScRQb-DXosWnqwpibAbgRtaCyCcOFP2QD4hPJa1-RP2_i0ueg/viewform?usp=dialog

Sheet 交流區
A1: 純粹的交流區，各位想留甚麼就留什麼吧 (或是有問題也可以詢問喔)
A2: 主編留 | B2: 主編7/3退伍，倒數中😌
A3: 粗線條工房AKN阿根 | B3: 我只是來說一下，你們整理這些資料的人都好帥😘
A4: 捲 | B4: 謝謝主編小編們，今年也全力支持！！
A5: 阿嵐章魚繪圖手作舖 | B5: 感謝各位每次整理的資訊QQ! 突然發現快登出國軍Online了! 最後衝刺!
A6: 阿嵐章魚繪圖手作舖 | B6: 註：我是社團【萬象澄澈】的友人/小精靈，有幫他先填一些資料，若造成不便的話，先在此說聲抱歉QQ
A7: 奇譚異書齋 | B7: 感謝主編小編們每次都這麼用心整理資訊，真的幫很大的忙~ 也在這預祝各位前輩完售，滿箱進場空箱回家
A8: DeityMark | B8: 謝謝你們每次都提前整理表單!真的幫了很多忙非常感謝主編及小編們!!!
A9: 雞塊 | B9: 感謝各位每次的整理!正要上來丟資料發現都被填好了神之效率QQQQ
A10: 主編留 | B10: 不會，這是我們應該要做的👍
A11: 蛙君 | B11: 感謝你們每年的資訊整理，今年異常炎熱，屆時請務必注意身體狀況QQ
A12: 秋森萬玩具店 | B12: 感謝【加帕利天藍怪預警中心】整理資訊與提供攤位宣傳，本店第一次參與擺攤，還請各位多指教

Sheet 0608更新名單
A1: 攤位名稱 | B1: 第一天 攤數 | C1: 第二天 攤位 | D1: 第三天 攤數
A2: 2.5 | B2: 0 | C2: 0 | D2: 1
A3: 825 | B3: 0 | C3: 1 | D3: 0
A4: #DREAMProject [JooA Cosplay] | B4: 0 | C4: 2 | D4: 2
A5: #DREAMProject Momo | B5: 0 | C5: 1 | D5: 1
A6: #DREAMProject Neneko | B6: 0 | C6: 2 | D6: 2
A7: #DREAMProject Shimo | B7: 0 | C7: 2 | D7: 2
A8: #DREAMProject Usagi羽咲 | B8: 0 | C8: 1 | D8: 1
A9: [CHOCOLATE SHOP] | B9: 2 | C9: 2 | D9: 0
A10: ～NEKONABE～ | B10: 0 | C10: 0 | D10: 1
A11: ～黑色布丁～ | B11: 0 | C11: 1 | D11: 1
A12: 【ZENTENG】 | B12: 0 | C12: 0 | D12: 1
A13: ‘+Ely Cosplay+ | B13: 0 | C13: 2 | D13: 2
A14: ＋そおの | B14: 0 | C14: 1 | D14: 2
A15: =+喵耳園魔法道具屋+ -> #ERROR! | B15: 2 | C15: 2 | D15: 0
A16: ♡可凡kofan0331 | B16: 2 | C16: 2 | D16: 0
A17: 0蛋黃女子由奈0 | B17: 0 | C17: 1 | D17: 1
A18: 1%小風 | B18: 1 | C18: 0 | D18: 0
A19: 23.4ド＆きのこのみ＆蜂蜜少女 | B19: 0 | C19: 1 | D19: 0
A20: 33号部屋 | B20: 1 | C20: 1 | D20: 0
A21: 404便利通販 | B21: 1 | C21: 0 | D21: 1
A22: 44c_isaac | B22: 1 | C22: 0 | D22: 1
A23: 5年目の放課後 | B23: 0 | C23: 1 | D23: 0
A24: 74 Production | B24: 0 | C24: 1 | D24: 0
A25: 7B鉛筆 | B25: 0 | C25: 0 | D25: 1
A26: 8七兔 | B26: 1 | C26: 0 | D26: 0
A27: A-Brei Atelier | B27: 0 | C27: 0 | D27: 2
... A1333: 鱷魚恐龍工作室 | B1333: 0 | C1333: 1 | D1333: 2

Sheet 整理進度
A1: =IFERROR(__xludf.DUMMYFUNCTION("IMPORTRANGE(""https://docs.google.com/spreadsheets/d/19o9oHQTeznK_QNRjWlIvU6k3aAhW0SjEDxdYIiw60QE"",""FF47!A:F"")"),"攤位總數") -> 攤位總數 | B1: =IFERROR(__xludf.DUMMYFUNCTION("""COMPUTED_VALUE"""),1336.0) -> 1336 | C1: =IFERROR(__xludf.DUMMYFUNCTION("""COMPUTED_VALUE"""),"攤位總數") -> 攤位總數 | D1: =IFERROR(__xludf.DUMMYFUNCTION("""COMPUTED_VALUE"""),1336.0) -> 1336
A2: =IFERROR(__xludf.DUMMYFUNCTION("""COMPUTED_VALUE"""),"無資料攤位") -> 無資料攤位 | B2: =IFERROR(__xludf.DUMMYFUNCTION("""COMPUTED_VALUE"""),68.0) -> 68 | C2: =IFERROR(__xludf.DUMMYFUNCTION("""COMPUTED_VALUE"""),"無資料攤位") -> 無資料攤位 | D2: =IFERROR(__xludf.DUMMYFUNCTION("""COMPUTED_VALUE"""),68.0) -> 68
A3: =IFERROR(__xludf.DUMMYFUNCTION("""COMPUTED_VALUE"""),"有攤位資料 (SNS、攤主資訊、本場販售資訊、品書)") -> 有攤位資料 (SNS、攤主資訊、本場販售資訊、品書) | B3: =IFERROR(__xludf.DUMMYFUNCTION("""COMPUTED_VALUE"""),621.0) -> 621 | C3: =IFERROR(__xludf.DUMMYFUNCTION("""COMPUTED_VALUE"""),"有攤位資料 (SNS、攤主資訊、本場販售資訊、品書)") -> 有攤位資料 (SNS、攤主資訊、本場販售資訊、品書) | D3: =IFERROR(__xludf.DUMMYFUNCTION("""COMPUTED_VALUE"""),621.0) -> 621 | E3: =IFERROR(__xludf.DUMMYFUNCTION("""COMPUTED_VALUE"""),"無SNS資料但有販售資訊") -> 無SNS資料但有販售資訊 | F3: =IFERROR(__xludf.DUMMYFUNCTION("""COMPUTED_VALUE"""),18.0) -> 18
C4: =IFERROR(__xludf.DUMMYFUNCTION("""COMPUTED_VALUE"""),"有FF47相關資訊攤位") -> 有FF47相關資訊攤位 | D4: =IFERROR(__xludf.DUMMYFUNCTION("""COMPUTED_VALUE"""),235.0) -> 235
C5: =IFERROR(__xludf.DUMMYFUNCTION("""COMPUTED_VALUE"""),"有預告攤位") -> 有預告攤位 | D5: =IFERROR(__xludf.DUMMYFUNCTION("""COMPUTED_VALUE"""),204.0) -> 204
C6: =IFERROR(__xludf.DUMMYFUNCTION("""COMPUTED_VALUE"""),"有品書攤位") -> 有品書攤位 | D6: =IFERROR(__xludf.DUMMYFUNCTION("""COMPUTED_VALUE"""),204.0) -> 204
A7: =IFERROR(__xludf.DUMMYFUNCTION("""COMPUTED_VALUE"""),"有FF47相關資訊攤位") -> 有FF47相關資訊攤位 | B7: =IFERROR(__xludf.DUMMYFUNCTION("""COMPUTED_VALUE"""),235.0) -> 235
A8: =IFERROR(__xludf.DUMMYFUNCTION("""COMPUTED_VALUE"""),"有預告攤位") -> 有預告攤位 | B8: =IFERROR(__xludf.DUMMYFUNCTION("""COMPUTED_VALUE"""),204.0) -> 204
A9: =IFERROR(__xludf.DUMMYFUNCTION("""COMPUTED_VALUE"""),"有品書攤位") -> 有品書攤位 | B9: =IFERROR(__xludf.DUMMYFUNCTION("""COMPUTED_VALUE"""),204.0) -> 204 | C9: =IFERROR(__xludf.DUMMYFUNCTION("""COMPUTED_VALUE"""),"有預告且有品書") -> 有預告且有品書 | D9: =IFERROR(__xludf.DUMMYFUNCTION("""COMPUTED_VALUE"""),"0") -> 0
D10: =IFERROR(__xludf.DUMMYFUNCTION("""COMPUTED_VALUE"""),73.0) -> 73
D11: =IFERROR(__xludf.DUMMYFUNCTION("""COMPUTED_VALUE"""),"有無縮圖") -> 有無縮圖 | E11: =IFERROR(__xludf.DUMMYFUNCTION("""COMPUTED_VALUE"""),"有縮圖") -> 有縮圖 | F11: =IFERROR(__xludf.DUMMYFUNCTION("""COMPUTED_VALUE"""),"無縮圖") -> 無縮圖
D12: =IFERROR(__xludf.DUMMYFUNCTION("""COMPUTED_VALUE"""),"有無縮圖") -> 有無縮圖 | E12: =IFERROR(__xludf.DUMMYFUNCTION("""COMPUTED_VALUE"""),262.0) -> 262 | F12: =IFERROR(__xludf.DUMMYFUNCTION("""COMPUTED_VALUE"""),1074.0) -> 1074
A13: =IFERROR(__xludf.DUMMYFUNCTION("""COMPUTED_VALUE"""),"時間") -> 時間 | B13: =IFERROR(__xludf.DUMMYFUNCTION("""COMPUTED_VALUE"""),"無資料攤位") -> 無資料攤位 | C13: =IFERROR(__xludf.DUMMYFUNCTION("""COMPUTED_VALUE"""),"有社群連結攤位") -> 有社群連結攤位 | D13: =IFERROR(__xludf.DUMMYFUNCTION("""COMPUTED_VALUE"""),"有FF47相關資訊攤位") -> 有FF47相關資訊攤位 | E13: =IFERROR(__xludf.DUMMYFUNCTION("""COMPUTED_VALUE"""),"有預告攤位") -> 有預告攤位 | F13: =IFERROR(__xludf.DUMMYFUNCTION("""COMPUTED_VALUE"""),"有品書攤位") -> 有品書攤位
A14: =IFERROR(__xludf.DUMMYFUNCTION("""COMPUTED_VALUE"""),46172.0) -> 46172 | B14: =IFERROR(__xludf.DUMMYFUNCTION("""COMPUTED_VALUE"""),384.0) -> 384 | C14: =IFERROR(__xludf.DUMMYFUNCTION("""COMPUTED_VALUE"""),926.0) -> 926 | D14: =IFERROR(__xludf.DUMMYFUNCTION("""COMPUTED_VALUE"""),"#N/A") -> #N/A | E14: =IFERROR(__xludf.DUMMYFUNCTION("""COMPUTED_VALUE"""),"#N/A") -> #N/A | F14: =IFERROR(__xludf.DUMMYFUNCTION("""COMPUTED_VALUE"""),"#N/A") -> #N/A
A15: =IFERROR(__xludf.DUMMYFUNCTION("""COMPUTED_VALUE"""),46173.0) -> 46173 | B15: =IFERROR(__xludf.DUMMYFUNCTION("""COMPUTED_VALUE"""),348.0) -> 348 | C15: =IFERROR(__xludf.DUMMYFUNCTION("""COMPUTED_VALUE"""),958.0) -> 958 | D15: =IFERROR(__xludf.DUMMYFUNCTION("""COMPUTED_VALUE"""),4.0) -> 4 | E15: =IFERROR(__xludf.DUMMYFUNCTION("""COMPUTED_VALUE"""),"#N/A") -> #N/A | F15: =IFERROR(__xludf.DUMMYFUNCTION("""COMPUTED_VALUE"""),"#N/A") -> #N/A
A16: =IFERROR(__xludf.DUMMYFUNCTION("""COMPUTED_VALUE"""),46174.0) -> 46174 | B16: =IFERROR(__xludf.DUMMYFUNCTION("""COMPUTED_VALUE"""),267.0) -> 267 | C16: =IFERROR(__xludf.DUMMYFUNCTION("""COMPUTED_VALUE"""),980.0) -> 980 | D16: =IFERROR(__xludf.DUMMYFUNCTION("""COMPUTED_VALUE"""),4.0) -> 4 | E16: =IFERROR(__xludf.DUMMYFUNCTION("""COMPUTED_VALUE"""),61.0) -> 61 | F16: =IFERROR(__xludf.DUMMYFUNCTION("""COMPUTED_VALUE"""),"#N/A") -> #N/A
A17: =IFERROR(__xludf.DUMMYFUNCTION("""COMPUTED_VALUE"""),46175.0) -> 46175 | B17: =IFERROR(__xludf.DUMMYFUNCTION("""COMPUTED_VALUE"""),243.0) -> 243 | C17: =IFERROR(__xludf.DUMMYFUNCTION("""COMPUTED_VALUE"""),968.0) -> 968 | D17: =IFERROR(__xludf.DUMMYFUNCTION("""COMPUTED_VALUE"""),5.0) -> 5 | E17: =IFERROR(__xludf.DUMMYFUNCTION("""COMPUTED_VALUE"""),99.0) -> 99 | F17: =IFERROR(__xludf.DUMMYFUNCTION("""COMPUTED_VALUE"""),"#N/A") -> #N/A
A18: =IFERROR(__xludf.DUMMYFUNCTION("""COMPUTED_VALUE"""),46176.0) -> 46176 | B18: =IFERROR(__xludf.DUMMYFUNCTION("""COMPUTED_VALUE"""),219.0) -> 219 | C18: =IFERROR(__xludf.DUMMYFUNCTION("""COMPUTED_VALUE"""),987.0) -> 987 | D18: =IFERROR(__xludf.DUMMYFUNCTION("""COMPUTED_VALUE"""),6.0) -> 6 | E18: =IFERROR(__xludf.DUMMYFUNCTION("""COMPUTED_VALUE"""),102.0) -> 102 | F18: =IFERROR(__xludf.DUMMYFUNCTION("""COMPUTED_VALUE"""),"#N/A") -> #N/A
A19: =IFERROR(__xludf.DUMMYFUNCTION("""COMPUTED_VALUE"""),46177.0) -> 46177 | B19: =IFERROR(__xludf.DUMMYFUNCTION("""COMPUTED_VALUE"""),195.0) -> 195 | C19: =IFERROR(__xludf.DUMMYFUNCTION("""COMPUTED_VALUE"""),1011.0) -> 1011 | D19: =IFERROR(__xludf.DUMMYFUNCTION("""COMPUTED_VALUE"""),6.0) -> 6 | E19: =IFERROR(__xludf.DUMMYFUNCTION("""COMPUTED_VALUE"""),102.0) -> 102 | F19: =IFERROR(__xludf.DUMMYFUNCTION("""COMPUTED_VALUE"""),"#N/A") -> #N/A
A20: =IFERROR(__xludf.DUMMYFUNCTION("""COMPUTED_VALUE"""),46178.0) -> 46178 | B20: =IFERROR(__xludf.DUMMYFUNCTION("""COMPUTED_VALUE"""),183.0) -> 183 | C20: =IFERROR(__xludf.DUMMYFUNCTION("""COMPUTED_VALUE"""),1020.0) -> 1020 | D20: =IFERROR(__xludf.DUMMYFUNCTION("""COMPUTED_VALUE"""),6.0) -> 6 | E20: =IFERROR(__xludf.DUMMYFUNCTION("""COMPUTED_VALUE"""),102.0) -> 102 | F20: =IFERROR(__xludf.DUMMYFUNCTION("""COMPUTED_VALUE"""),1.0) -> 1
A21: =IFERROR(__xludf.DUMMYFUNCTION("""COMPUTED_VALUE"""),46179.0) -> 46179 | B21: =IFERROR(__xludf.DUMMYFUNCTION("""COMPUTED_VALUE"""),164.0) -> 164 | C21: =IFERROR(__xludf.DUMMYFUNCTION("""COMPUTED_VALUE"""),1035.0) -> 1035 | D21: =IFERROR(__xludf.DUMMYFUNCTION("""COMPUTED_VALUE"""),6.0) -> 6 | E21: =IFERROR(__xludf.DUMMYFUNCTION("""COMPUTED_VALUE"""),106.0) -> 106 | F21: =IFERROR(__xludf.DUMMYFUNCTION("""COMPUTED_VALUE"""),1.0) -> 1
A22: =IFERROR(__xludf.DUMMYFUNCTION("""COMPUTED_VALUE"""),46180.0) -> 46180 | B22: =IFERROR(__xludf.DUMMYFUNCTION("""COMPUTED_VALUE"""),164.0) -> 164 | C22: =IFERROR(__xludf.DUMMYFUNCTION("""COMPUTED_VALUE"""),1034.0) -> 1034 | D22: =IFERROR(__xludf.DUMMYFUNCTION("""COMPUTED_VALUE"""),7.0) -> 7 | E22: =IFERROR(__xludf.DUMMYFUNCTION("""COMPUTED_VALUE"""),106.0) -> 106 | F22: =IFERROR(__xludf.DUMMYFUNCTION("""COMPUTED_VALUE"""),1.0) -> 1
A23: =IFERROR(__xludf.DUMMYFUNCTION("""COMPUTED_VALUE"""),46181.0) -> 46181 | B23: =IFERROR(__xludf.DUMMYFUNCTION("""COMPUTED_VALUE"""),146.0) -> 146 | C23: =IFERROR(__xludf.DUMMYFUNCTION("""COMPUTED_VALUE"""),1049.0) -> 1049 | D23: =IFERROR(__xludf.DUMMYFUNCTION("""COMPUTED_VALUE"""),9.0) -> 9 | E23: =IFERROR(__xludf.DUMMYFUNCTION("""COMPUTED_VALUE"""),106.0) -> 106 | F23: =IFERROR(__xludf.DUMMYFUNCTION("""COMPUTED_VALUE"""),1.0) -> 1
A24: =IFERROR(__xludf.DUMMYFUNCTION("""COMPUTED_VALUE"""),46182.0) -> 46182 | B24: =IFERROR(__xludf.DUMMYFUNCTION("""COMPUTED_VALUE"""),130.0) -> 130 | C24: =IFERROR(__xludf.DUMMYFUNCTION("""COMPUTED_VALUE"""),1057.0) -> 1057 | D24: =IFERROR(__xludf.DUMMYFUNCTION("""COMPUTED_VALUE"""),9.0) -> 9 | E24: =IFERROR(__xludf.DUMMYFUNCTION("""COMPUTED_VALUE"""),114.0) -> 114 | F24: =IFERROR(__xludf.DUMMYFUNCTION("""COMPUTED_VALUE"""),1.0) -> 1
A25: =IFERROR(__xludf.DUMMYFUNCTION("""COMPUTED_VALUE"""),46183.0) -> 46183 | B25: =IFERROR(__xludf.DUMMYFUNCTION("""COMPUTED_VALUE"""),117.0) -> 117 | C25: =IFERROR(__xludf.DUMMYFUNCTION("""COMPUTED_VALUE"""),1069.0) -> 1069 | D25: =IFERROR(__xludf.DUMMYFUNCTION("""COMPUTED_VALUE"""),9.0) -> 9 | E25: =IFERROR(__xludf.DUMMYFUNCTION("""COMPUTED_VALUE"""),114.0) -> 114 | F25: =IFERROR(__xludf.DUMMYFUNCTION("""COMPUTED_VALUE"""),1.0) -> 1
A26: =IFERROR(__xludf.DUMMYFUNCTION("""COMPUTED_VALUE"""),46185.0) -> 46185 | B26: =IFERROR(__xludf.DUMMYFUNCTION("""COMPUTED_VALUE"""),117.0) -> 117 | C26: =IFERROR(__xludf.DUMMYFUNCTION("""COMPUTED_VALUE"""),1069.0) -> 1069 | D26: =IFERROR(__xludf.DUMMYFUNCTION("""COMPUTED_VALUE"""),9.0) -> 9 | E26: =IFERROR(__xludf.DUMMYFUNCTION("""COMPUTED_VALUE"""),114.0) -> 114 | F26: =IFERROR(__xludf.DUMMYFUNCTION("""COMPUTED_VALUE"""),1.0) -> 1
A27: =IFERROR(__xludf.DUMMYFUNCTION("""COMPUTED_VALUE"""),46186.0) -> 46186 | B27: =IFERROR(__xludf.DUMMYFUNCTION("""COMPUTED_VALUE"""),117.0) -> 117 | C27: =IFERROR(__xludf.DUMMYFUNCTION("""COMPUTED_VALUE"""),1060.0) -> 1060 | D27: =IFERROR(__xludf.DUMMYFUNCTION("""COMPUTED_VALUE"""),9.0) -> 9 | E27: =IFERROR(__xludf.DUMMYFUNCTION("""COMPUTED_VALUE"""),123.0) -> 123 | F27: =IFERROR(__xludf.DUMMYFUNCTION("""COMPUTED_VALUE"""),1.0) -> 1
A28: =IFERROR(__xludf.DUMMYFUNCTION("""COMPUTED_VALUE"""),46187.0) -> 46187 | B28: =IFERROR(__xludf.DUMMYFUNCTION("""COMPUTED_VALUE"""),117.0) -> 117 | C28: =IFERROR(__xludf.DUMMYFUNCTION("""COMPUTED_VALUE"""),1067.0) -> 1067 | D28: =IFERROR(__xludf.DUMMYFUNCTION("""COMPUTED_VALUE"""),10.0) -> 10 | E28: =IFERROR(__xludf.DUMMYFUNCTION("""COMPUTED_VALUE"""),123.0) -> 123 | F28: =IFERROR(__xludf.DUMMYFUNCTION("""COMPUTED_VALUE"""),1.0) -> 1
A29: =IFERROR(__xludf.DUMMYFUNCTION("""COMPUTED_VALUE"""),46188.0) -> 46188 | B29: =IFERROR(__xludf.DUMMYFUNCTION("""COMPUTED_VALUE"""),117.0) -> 117 | C29: =IFERROR(__xludf.DUMMYFUNCTION("""COMPUTED_VALUE"""),1065.0) -> 1065 | D29: =IFERROR(__xludf.DUMMYFUNCTION("""COMPUTED_VALUE"""),12.0) -> 12 | E29: =IFERROR(__xludf.DUMMYFUNCTION("""COMPUTED_VALUE"""),123.0) -> 123 | F29: =IFERROR(__xludf.DUMMYFUNCTION("""COMPUTED_VALUE"""),1.0) -> 1
A30: =IFERROR(__xludf.DUMMYFUNCTION("""COMPUTED_VALUE"""),46189.0) -> 46189 | B30: =IFERROR(__xludf.DUMMYFUNCTION("""COMPUTED_VALUE"""),117.0) -> 117 | C30: =IFERROR(__xludf.DUMMYFUNCTION("""COMPUTED_VALUE"""),1065.0) -> 1065 | D30: =IFERROR(__xludf.DUMMYFUNCTION("""COMPUTED_VALUE"""),12.0) -> 12 | E30: =IFERROR(__xludf.DUMMYFUNCTION("""COMPUTED_VALUE"""),123.0) -> 123 | F30: =IFERROR(__xludf.DUMMYFUNCTION("""COMPUTED_VALUE"""),1.0) -> 1
A31: =IFERROR(__xludf.DUMMYFUNCTION("""COMPUTED_VALUE"""),46190.0) -> 46190 | B31: =IFERROR(__xludf.DUMMYFUNCTION("""COMPUTED_VALUE"""),117.0) -> 117 | C31: =IFERROR(__xludf.DUMMYFUNCTION("""COMPUTED_VALUE"""),1065.0) -> 1065 | D31: =IFERROR(__xludf.DUMMYFUNCTION("""COMPUTED_VALUE"""),12.0) -> 12 | E31: =IFERROR(__xludf.DUMMYFUNCTION("""COMPUTED_VALUE"""),123.0) -> 123 | F31: =IFERROR(__xludf.DUMMYFUNCTION("""COMPUTED_VALUE"""),1.0) -> 1
A32: =IFERROR(__xludf.DUMMYFUNCTION("""COMPUTED_VALUE"""),46191.0) -> 46191 | B32: =IFERROR(__xludf.DUMMYFUNCTION("""COMPUTED_VALUE"""),117.0) -> 117 | C32: =IFERROR(__xludf.DUMMYFUNCTION("""COMPUTED_VALUE"""),1065.0) -> 1065 | D32: =IFERROR(__xludf.DUMMYFUNCTION("""COMPUTED_VALUE"""),12.0) -> 12 | E32: =IFERROR(__xludf.DUMMYFUNCTION("""COMPUTED_VALUE"""),123.0) -> 123 | F32: =IFERROR(__xludf.DUMMYFUNCTION("""COMPUTED_VALUE"""),1.0) -> 1
A33: =IFERROR(__xludf.DUMMYFUNCTION("""COMPUTED_VALUE"""),46192.0) -> 46192 | B33: =IFERROR(__xludf.DUMMYFUNCTION("""COMPUTED_VALUE"""),117.0) -> 117 | C33: =IFERROR(__xludf.DUMMYFUNCTION("""COMPUTED_VALUE"""),1065.0) -> 1065 | D33: =IFERROR(__xludf.DUMMYFUNCTION("""COMPUTED_VALUE"""),12.0) -> 12 | E33: =IFERROR(__xludf.DUMMYFUNCTION("""COMPUTED_VALUE"""),123.0) -> 123 | F33: =IFERROR(__xludf.DUMMYFUNCTION("""COMPUTED_VALUE"""),1.0) -> 1
A34: =IFERROR(__xludf.DUMMYFUNCTION("""COMPUTED_VALUE"""),46193.0) -> 46193 | B34: =IFERROR(__xludf.DUMMYFUNCTION("""COMPUTED_VALUE"""),117.0) -> 117 | C34: =IFERROR(__xludf.DUMMYFUNCTION("""COMPUTED_VALUE"""),1065.0) -> 1065 | D34: =IFERROR(__xludf.DUMMYFUNCTION("""COMPUTED_VALUE"""),12.0) -> 12 | E34: =IFERROR(__xludf.DUMMYFUNCTION("""COMPUTED_VALUE"""),123.0) -> 123 | F34: =IFERROR(__xludf.DUMMYFUNCTION("""COMPUTED_VALUE"""),1.0) -> 1
A35: =IFERROR(__xludf.DUMMYFUNCTION("""COMPUTED_VALUE"""),46194.0) -> 46194 | B35: =IFERROR(__xludf.DUMMYFUNCTION("""COMPUTED_VALUE"""),116.0) -> 116 | C35: =IFERROR(__xludf.DUMMYFUNCTION("""COMPUTED_VALUE"""),1065.0) -> 1065 | D35: =IFERROR(__xludf.DUMMYFUNCTION("""COMPUTED_VALUE"""),13.0) -> 13 | E35: =IFERROR(__xludf.DUMMYFUNCTION("""COMPUTED_VALUE"""),123.0) -> 123 | F35: =IFERROR(__xludf.DUMMYFUNCTION("""COMPUTED_VALUE"""),1.0) -> 1
A36: =IFERROR(__xludf.DUMMYFUNCTION("""COMPUTED_VALUE"""),46195.0) -> 46195 | B36: =IFERROR(__xludf.DUMMYFUNCTION("""COMPUTED_VALUE"""),116.0) -> 116 | C36: =IFERROR(__xludf.DUMMYFUNCTION("""COMPUTED_VALUE"""),1065.0) -> 1065 | D36: =IFERROR(__xludf.DUMMYFUNCTION("""COMPUTED_VALUE"""),13.0) -> 13 | E36: =IFERROR(__xludf.DUMMYFUNCTION("""COMPUTED_VALUE"""),123.0) -> 123 | F36: =IFERROR(__xludf.DUMMYFUNCTION("""COMPUTED_VALUE"""),1.0) -> 1
A37: =IFERROR(__xludf.DUMMYFUNCTION("""COMPUTED_VALUE"""),46196.0) -> 46196 | B37: =IFERROR(__xludf.DUMMYFUNCTION("""COMPUTED_VALUE"""),116.0) -> 116 | C37: =IFERROR(__xludf.DUMMYFUNCTION("""COMPUTED_VALUE"""),1065.0) -> 1065 | D37: =IFERROR(__xludf.DUMMYFUNCTION("""COMPUTED_VALUE"""),13.0) -> 13 | E37: =IFERROR(__xludf.DUMMYFUNCTION("""COMPUTED_VALUE"""),123.0) -> 123 | F37: =IFERROR(__xludf.DUMMYFUNCTION("""COMPUTED_VALUE"""),1.0) -> 1
A38: =IFERROR(__xludf.DUMMYFUNCTION("""COMPUTED_VALUE"""),46197.0) -> 46197 | B38: =IFERROR(__xludf.DUMMYFUNCTION("""COMPUTED_VALUE"""),116.0) -> 116 | C38: =IFERROR(__xludf.DUMMYFUNCTION("""COMPUTED_VALUE"""),1065.0) -> 1065 | D38: =IFERROR(__xludf.DUMMYFUNCTION("""COMPUTED_VALUE"""),13.0) -> 13 | E38: =IFERROR(__xludf.DUMMYFUNCTION("""COMPUTED_VALUE"""),123.0) -> 123 | F38: =IFERROR(__xludf.DUMMYFUNCTION("""COMPUTED_VALUE"""),1.0) -> 1
A39: =IFERROR(__xludf.DUMMYFUNCTION("""COMPUTED_VALUE"""),46198.0) -> 46198 | B39: =IFERROR(__xludf.DUMMYFUNCTION("""COMPUTED_VALUE"""),116.0) -> 116 | C39: =IFERROR(__xludf.DUMMYFUNCTION("""COMPUTED_VALUE"""),1065.0) -> 1065 | D39: =IFERROR(__xludf.DUMMYFUNCTION("""COMPUTED_VALUE"""),13.0) -> 13 | E39: =IFERROR(__xludf.DUMMYFUNCTION("""COMPUTED_VALUE"""),123.0) -> 123 | F39: =IFERROR(__xludf.DUMMYFUNCTION("""COMPUTED_VALUE"""),1.0) -> 1
A40: =IFERROR(__xludf.DUMMYFUNCTION("""COMPUTED_VALUE"""),46199.0) -> 46199 | B40: =IFERROR(__xludf.DUMMYFUNCTION("""COMPUTED_VALUE"""),116.0) -> 116 | C40: =IFERROR(__xludf.DUMMYFUNCTION("""COMPUTED_VALUE"""),1064.0) -> 1064 | D40: =IFERROR(__xludf.DUMMYFUNCTION("""COMPUTED_VALUE"""),14.0) -> 14 | E40: =IFERROR(__xludf.DUMMYFUNCTION("""COMPUTED_VALUE"""),122.0) -> 122 | F40: =IFERROR(__xludf.DUMMYFUNCTION("""COMPUTED_VALUE"""),1.0) -> 1
...

Sheet DAY1
A1: 攤位編號 | B1: 攤位名稱
A2: A01,A02 | B2: OriginZero
A3: A03 | B3: MAI
A4: A04 | B4: 心重力動漫工作室
A5: A05,A06 | B5: 蒼銀之星
A6: A07 | B6: 殺必死天國
A7: A08,A09 | B7: 闇夢館
A8: A10,A11 | B8: 三色坊
A9: A12,A13 | B9: 有害蕈類集會所
A10: A14 | B10: BsWs黑星白星
A11: A15,A16 | B11: 黑蛛白蛛
A12: A17,A18 | B12: 御狐亭
... A285: J07,J08 | B285: 克特小舖
A286: J09,J10 | B286: =+喵耳園魔法道具屋+ -> #ERROR!
A287: J11 | B287: 三分糖手作中
A288: J12 | B288: 光影之下
A289: J13,J14 | B289: 瑪魯瑪魯手創
A290: J15 | B290: 愛做夢的人
A291: J16 | B291: Cunomon庫糯夢
A292: J17,J18 | B292: 模型優創
A293: J19 | B293: ブルーブルルー
A294: J20 | B294: 奶油玉米的呆毛
A295: J21,J22 | B295: FuwaFuwa軟趴趴
A296: J23 | B296: M片 m-pien
A297: J24 | B297: RayP
A298: J25 | B298: M.O.K.茶包
... A713: W41,W42 | B713: 雨波HaneAme

Sheet 工作表25
A1: 攤位名稱 | B1: 筆名 | C1: 第一天 | D1: 第二天 | E1: 第三天 | F1: 創作者類型 | G1: 二創參考作品 (原創免填) | H1: 商品年齡分類 | I1: 作品類型 (原創、二創) | J1: 販售資訊 | K1: 特殊標籤或備註 | L1: {={ "有無資料"; BYROW(R5:AL2391, LAMBDA(currRow, COUNTA(currRow)>0)) }} -> 有無資料 | M1: {={ "有無販售資訊"; BYROW(H5:K2391, LAMBDA(currRow,COUNTA(currRow)>0)) }} -> 有無販售資訊 | N1: {={"有無預告";MAP(AM5:AM2391, LAMBDA(cell, ISTEXT(cell)))}} -> 有無預告 | O1: {={"有無品書";MAP(AN5:AN2391, LAMBDA(cell, ISTEXT(cell)))}} -> 有無品書 | P1: 資料信心度 | Q1: 印量調查 請至印調區填寫 | R1: FB (1) | S1: FB (2) | T1: Bluesky (1) | U1: Bluesky (2) | V1: TWITTER (1) | W1: TWITTER (2) | X1: PLURK | Y1: Pixiv | Z1: Fanbox | AA1: Fantia | AB1: 可洛斯 | AC1: 其他贊助平台 | AD1: IG | AE1: YOUTUBE | AF1: TWITCH | AG1: LINE | AH1: DISCORD | AI1: 巴哈姆特 | AJ1: 官方網站 | AK1: Linktree等連結整合網頁 | AL1: 其他連結 | AM1: 預告 | AN1: 品書 | AO1: 預購/通販 | AP1: 縮圖[請備註] | AQ1: 是否有縮圖 | AR1: 試閱
A2: KAWORU卡歐露 | C2: F25,F26 | D2: F25 | F2: 繪師, 台灣Vtuber個人勢 | G2: VTuber 小森クマ | H2: 一般 | I2: 原創 | J2: 💠同人誌【PRIVATA WARDROBE vol.2】250元 💠短髮立牌 💠拍立得 💠明信片 💠飯友 💠新刊小套組 700元 (同人誌+短髮立牌+拍立得+明信片+飯友) 💠護士立牌 💠護士飯友 💠新刊中套組 1300元 (小套組+護士立牌+護士飯友) 💠鎖邊滑鼠墊 600元 💠造型寫字板 💠小吊飾 💠新刊大套組 2000元 (中套組 + 滑鼠墊+寫字板+小吊飾) | L2: TRUE | M2: TRUE | N2: FALSE | O2: TRUE | Q2: {=IFERROR(INDEX('印量調查區'!G:G, MATCH(A2, '印量調查區'!A:A, 0)), "")} | R2: https://www.facebook.com/Kaworu1030 | V2: https://twitter.com/kaworu1030 | W2: https://twitter.com/kaworu_art | X2: https://www.plurk.com/kaworu1030 | Y2: https://www.pixiv.net/users/1671960 | AC2: https://www.patreon.com/Kaworu | AD2: https://www.instagram.com/kaworu1030/ | AF2: https://www.twitch.tv/kaworu1030 | AH2: https://discord.gg/pczy9uBGHd | AK2: https://lit.link/en/kaworu1030 | AM2: https://www.myacg.com.tw/goods_detail.php?gid=6637488 https://www.facebook.com/reel/1758198108184216/ | AN2: https://www.facebook.com/Kaworu1030/posts/pfbid02ty2hERdzKqeu9cJtgGhLQoq37SKdLJxxvUcyoZwL1ztfryAE2hYmF2iRHi5XiNcJl | AO2: https://www.myacg.com.tw/goods_detail.php?gid=6637488 | AQ2: =IFERROR(__xludf.DUMMYFUNCTION("IF(IFERROR(VLOOKUP(A2, IMPORTRANGE(""https://docs.google.com/spreadsheets/d/1eazy315Oas8TkAoTsdzUl6gNf3VsnwZeSo-bRfkZzOs"", ""工作表1!A:B""), 2, FALSE), """") <> """", ""有縮圖"", ""無縮圖"")"),"無縮圖") -> 無縮圖
A3: 枳枳zhizih | E3: R14 | F3: Coser | G3: 2.5次元的誘惑 | I3: 二創 | J3: 💠寫真集【2.5次元的天使】800元 💠寫真集套組 2400元 (寫真集 + 徽章 + 拍立得 + 吊飾 + 電子檔) 💠生寫真3枚 100元 💠圓形徽章 100元 💠拍立得 300元 💠迷你CD造型吊飾 350元 💠寫真電子檔700元 | L3: TRUE | M3: TRUE | N3: FALSE | O3: TRUE | Q3: {=IFERROR(INDEX('印量調查區'!G:G, MATCH(A3, '印量調查區'!A:A, 0)), "")} | AD3: https://www.instagram.com/zhizih0501/ | AN3: https://www.facebook.com/permalink.php?story_fbid=pfbid0T63kJejsvXVNETYmxr8mWaRKwheTrjtHFagQekHg824kPK5tzvwefGNy2xcqcx9Hl&id=61577006345762 | AQ3: =IFERROR(__xludf.DUMMYFUNCTION("IF(IFERROR(VLOOKUP(A3, IMPORTRANGE(""https://docs.google.com/spreadsheets/d/1eazy315Oas8TkAoTsdzUl6gNf3VsnwZeSo-bRfkZzOs"", ""工作表1!A:B""), 2, FALSE), """") <> """", ""有縮圖"", ""無縮圖"")"),"無縮圖") -> 無縮圖
A4: 蛞蝓.菠菜丼 | D4: P32[寄] | E4: P31,P32 | F4: 繪師 | G4: 2.5次元的誘惑，戀上換裝娃娃, 蔚藍檔案 / Blue Archive / ブルーアーカイブ | H4: R18, 一般 | I4: 二創 | J4: 💠海夢抱枕 2300元 💠掛軸 500元 💠等身掛軸 1000元 💠壓克力立牌 350元 💠防水桌墊 600元 | L4: TRUE | M4: TRUE | N4: FALSE | O4: TRUE | Q4: {=IFERROR(INDEX('印量調查區'!G:G, MATCH(A4, '印量調查區'!A:A, 0)), "")} | R4: https://www.facebook.com/SLUGTT666/ | V4: https://twitter.com/henny60225 | Y4: https://www.pixiv.net/users/14155307 | AN4: https://www.facebook.com/share/p/16gCNYqRoX/ | AQ4: =IFERROR(__xludf.DUMMYFUNCTION("IF(IFERROR(VLOOKUP(A4, IMPORTRANGE(""https://docs.google.com/spreadsheets/d/1eazy315Oas8TkAoTsdzUl6gNf3VsnwZeSo-bRfkZzOs"", ""工作表1!A:B""), 2, FALSE), """") <> """", ""有縮圖"", ""無縮圖"")"),"無縮圖") -> 無縮圖
A5: 共聚物精靈Copolymer Wizard | B5: 間宮ゆき/シマウマの頭 | C5: D33 | F5: 繪師 | G5: 千戀萬花、柚子社 | H5: 一般 | I5: 二創 | J5: 💠同人誌【Yuzusoft】200元 💠胸章 50元 💠15公分立牌 300元 💠小吊飾 50元 | L5: TRUE | M5: TRUE | N5: FALSE | O5: TRUE | Q5: {=IFERROR(INDEX('印量調查區'!G:G, MATCH(A5, '印量調查區'!A:A, 0)), "")} | R5: https://www.facebook.com/CopolymerWizard/ | V5: https://twitter.com/jiangongyouji1?fbclid=IwAR3pDPJdZv_CR-KCd4yvnhd0iBTTKTlLxY3PuioEuDFYVyCbxnApP_HZdic | W5: https://x.com/a29573359 | AI5: 巴哈姆特 | AN5: https://www.facebook.com/jeff.shu.7/posts/pfbid09TJGPK8Cd3F9GmTsnbRKnW2mtz5TNLa2Vc4XwRh8bq2eoKXEw1LX5nUZJoEAWPyvl | AQ5: =IFERROR(__xludf.DUMMYFUNCTION("IF(IFERROR(VLOOKUP(A5, IMPORTRANGE(""https://docs.google.com/spreadsheets/d/1eazy315Oas8TkAoTsdzUl6gNf3VsnwZeSo-bRfkZzOs"", ""工作表1!A:B""), 2, FALSE), """") <> """", ""有縮圖"", ""無縮圖"")"),"無縮圖") -> 無縮圖
A6: 全糖里斯 | B6: 里斯 | C6: V41 [寄] | D6: K17,K18 [寄] | E6: E31,E32 [寄] | F6: 繪師 | G6: 子午計畫 | H6: 一般 | I6: 二創 | J6: 壓克力色紙、Rei約會立牌、飯友、FF46套組 800元 | L6: TRUE | M6: TRUE | N6: FALSE | O6: FALSE | R6: https://www.facebook.com/ke.li.si.439192 | V6: https://x.com/tobunchudoku?fbclid=IwY2xjawPu6g5leHRuA2FlbQIxMABicmlkETE5ejhSdWUxNU5waFBwa2hac3J0YwZhcHBfaWQQMjIyMDM5MTc4ODIwMDg5MgABHthoKkK3Ue6M2MPpIUtI-5Gp7ecdon3dT0iM8JTflKc6K1VGJcwpGWGpJp9C_aem_psNr4gRaB1bGWyEzBKc-yA | AN6: https://www.facebook.com/photo/?fbid=2385347228593739&set=pcb.2385355538592908 | AQ6: =IFERROR(__xludf.DUMMYFUNCTION("IF(IFERROR(VLOOKUP(A6, IMPORTRANGE(""https://docs.google.com/spreadsheets/d/1eazy315Oas8TkAoTsdzUl6gNf3VsnwZeSo-bRfkZzOs"", ""工作表1!A:B""), 2, FALSE), """") <> """", ""有縮圖"", ""無縮圖"")"),"無縮圖") -> 無縮圖
A7: 米型自動複製單元 | B7: 米登卡爾 | C7: M36 | D7: M36 | F7: 繪師 | G7: 子午計畫,澪Rei | H7: 一般 | I7: 二創 | J7: 《有狸出沒注意報》刊物：NT.150 壓克力吊飾：NT.150 立牌：NT.350 燙金票卡：套組限定 不織布袋：套組限定 | L7: TRUE | M7: TRUE | N7: TRUE | O7: TRUE | Q7: {=IFERROR(INDEX('印量調查區'!G:G, MATCH(A7, '印量調查區'!A:A, 0)), "")} | R7: https://www.facebook.com/xi.jun.779/ | V7: https://twitter.com/setoharukano_12?fbclid=IwAR1HQF8M2DXctPL16LGe0DpaiF_9nInlCNQR1Fvo6Ysev2M7IPZhkNH6DNY | X7: https://www.plurk.com/Siawasenosekai | Y7: https://www.pixiv.net/users/14655223 | AN7: https://www.facebook.com/share/p/1C8L3KqAjz/ | AO7: https://www.myacg.com.tw/goods_detail.php?gid=6760962 | AQ7: =IFERROR(__xludf.DUMMYFUNCTION("IF(IFERROR(VLOOKUP(A7, IMPORTRANGE(""https://docs.google.com/spreadsheets/d/1eazy315Oas8TkAoTsdzUl6gNf3VsnwZeSo-bRfkZzOs"", ""工作表1!A:B""), 2, FALSE), """") <> """", ""有縮圖"", ""無縮圖"")"),"有縮圖") -> 有縮圖
A8: 虛擬家長會 | C8: V41 [寄] | D8: K17,K18 [寄] | E8: E31,E32 | F8: 繪師 | G8: 子午計劃 | H8: 一般 | I8: 二創 | J8: Kirali 約會立牌 350元 | L8: TRUE | M8: TRUE | N8: TRUE | O8: TRUE | Q8: {=IFERROR(INDEX('印量調查區'!G:G, MATCH(A8, '印量調查區'!A:A, 0)), "")} | R8: https://www.facebook.com/yu.an.chen.684671 | AN8: https://www.facebook.com/yu.an.chen.684671/posts/pfbid0gBAwxywRFnAS9Lfs3FjgQgXZ8Yq9GNYX6d83A4JeWbbNbYtqyHdVfRdAP3Y3ECYgl | AQ8: =IFERROR(__xludf.DUMMYFUNCTION("IF(IFERROR(VLOOKUP(A8, IMPORTRANGE(""https://docs.google.com/spreadsheets/d/1eazy315Oas8TkAoTsdzUl6gNf3VsnwZeSo-bRfkZzOs"", ""工作表1!A:B""), 2, FALSE), """") <> """", ""有縮圖"", ""無縮圖"")"),"無縮圖") -> 無縮圖
A9: に向思考 | B9: 貓崎 葵 | D9: V01 | E9: V09,V10 | F9: 繪師 | G9: 小智是女孩啦！ | H9: R18 | I9: 二創 | L9: TRUE | M9: TRUE | N9: FALSE | O9: TRUE | Q9: {=IFERROR(INDEX('印量調查區'!G:G, MATCH(A9, '印量調查區'!A:A, 0)), "")} | V9: https://x.com/NekosakiAoi | X9: https://www.plurk.com/sss4361 | Y9: https://www.pixiv.net/users/3318611 | AI9: https://home.gamer.com.tw/homeindex.php?owner=louieca400 | AQ9: =IFERROR(__xludf.DUMMYFUNCTION("IF(IFERROR(VLOOKUP(A9, IMPORTRANGE(""https://docs.google.com/spreadsheets/d/1eazy315Oas8TkAoTsdzUl6gNf3VsnwZeSo-bRfkZzOs"", ""工作表1!A:B""), 2, FALSE), """") <> """", ""有縮圖"", ""無縮圖"")"),"有縮圖") -> 有縮圖
A10: Bygin-白巾 | B10: Bygin-白巾 | C10: U43,U44 | D10: U21,U22 | E10: U21,U22 | F10: 繪師 | G10: 不時輕聲地以俄語遮羞的鄰座艾莉同學 | H10: R15, R18 | I10: 二創 | J10: 同人誌、龍心小悅套組 200元、捲到不行大套組 1000元 (本子+明信片+掛軸+杯墊+手機架+不織布提袋) | L10: TRUE | M10: TRUE | N10: FALSE | O10: TRUE | Q10: {=IFERROR(INDEX('印量調查區'!G:G, MATCH(A10, '印量調查區'!A:A, 0)), "")} | R10: https://www.facebook.com/byginartwork/ | S10: https://www.facebook.com/bygin01/ | T10: https://bsky.app/profile/bygin.bsky.social | V10: https://twitter.com/ByginArtist | W10: https://x.com/ByGin712576 | X10: https://www.plurk.com/chenyangyang100 | Y10: https://www.pixiv.net/users/13795156 | Z10: https://bygin.fanbox.cc/ | AC10: https://www.patreon.com/c/bygin?vanity=user | AD10: https://www.instagram.com/bygin_artwork/?hl=zh-tw | AH10: https://discord.gg/qCs4qX3T9x | AI10: https://home.gamer.com.tw/creation.php?owner=chenyang100 | AL10: https://linkgoods.com/bygin | AM10: https://www.myacg.com.tw/goods_detail.php?gid=6618082 https://www.myacg.com.tw/goods_detail.php?gid=6618075 https://www.myacg.com.tw/goods_detail.php?gid=6618072 | AN10: https://drive.google.com/drive/folders/1AYddpb6Rs63qS3q43DT0Id6tFaFLqJTu?usp=sharing | AO10: https://www.myacg.com.tw/goods_detail.php?gid=6618082 https://www.myacg.com.tw/goods_detail.php?gid=6618075 https://www.myacg.com.tw/goods_detail.php?gid=6618072 https://www.myacg.com.tw/seller_market.php?seller=693547 | AQ10: =IFERROR(__xludf.DUMMYFUNCTION("IF(IFERROR(VLOOKUP(A10, IMPORTRANGE(""https://docs.google.com/spreadsheets/d/1eazy315Oas8TkAoTsdzUl6gNf3VsnwZeSo-bRfkZzOs"", ""工作表1!A:B""), 2, FALSE), """") <> """", ""有縮圖"", ""無縮圖"")"),"有縮圖") -> 有縮圖 | AR10: https://www.facebook.com/byginartwork/posts/pfbid02AAZVLpecrEFT6XzJ2WQEhsYdw95qdueiUp9N8K9Znm5CaLDJhfyZ2TD3M6UkdJCdl
A11: 壞菇社 | B11: 凡爾賽菇雞三世、4why | C11: T43,T44 | D11: T43,T44 | F11: 繪師 | G11: 五等分的新娘 | H11: R18 | I11: 二創 | J11: 同人誌 100元 - 500元、桌墊 600元、掛軸 600元、立牌 300元 | L11: TRUE | M11: TRUE | N11: TRUE | O11: TRUE | Q11: {=IFERROR(INDEX('印量調查區'!G:G, MATCH(A11, '印量調查區'!A:A, 0)), "")} | R11: https://www.facebook.com/MARK4why/ | V11: https://twitter.com/ChickeIII | X11: https://www.plurk.com/fg3517 | Y11: https://www.pixiv.net/users/9752301 | AM11: https://www.plurk.com/p/3i6qaejivv | AN11: https://www.facebook.com/MARK4why/posts/pfbid09ECDKTqStxVzmmJjCP7u4hPDURCBgVc15opYujH8n2xonKYT7wtVDRxisyANfh2Ul | AQ11: =IFERROR(__xludf.DUMMYFUNCTION("IF(IFERROR(VLOOKUP(A11, IMPORTRANGE(""https://docs.google.com/spreadsheets/d/1eazy315Oas8TkAoTsdzUl6gNf3VsnwZeSo-bRfkZzOs"", ""工作表1!A:B""), 2, FALSE), """") <> """", ""有縮圖"", ""無縮圖"")"),"無縮圖") -> 無縮圖
A12: グリモア | B12: マカ | C12: N12 | D12: P39, P40 [寄] | F12: 繪師 | G12: 公主連結 | H12: R18 | I12: 二創 | J12: 💠同人誌新刊 400元 💠入浴劑100元 💠立牌共浴套組 2000元 💠既刊 💠限定掛軸 600元 | L12: TRUE | M12: TRUE | N12: TRUE | O12: TRUE | Q12: {=IFERROR(INDEX('印量調查區'!G:G, MATCH(A12, '印量調查區'!A:A, 0)), "")} | V12: https://x.com/a83d8 | X12: https://www.plurk.com/Maca105 | Y12: https://www.pixiv.net/users/834194 | Z12: https://macaca12.fanbox.cc/ | AL12: https://skeb.jp/@a83d8 | AN12: https://www.plurk.com/p/3i8zolr211 | AQ12: =IFERROR(__xludf.DUMMYFUNCTION("IF(IFERROR(VLOOKUP(A12, IMPORTRANGE(""https://docs.google.com/spreadsheets/d/1eazy315Oas8TkAoTsdzUl6gNf3VsnwZeSo-bRfkZzOs"", ""工作表1!A:B""), 2, FALSE), """") <> """", ""有縮圖"", ""無縮圖"")"),"有縮圖") -> 有縮圖
